Workbook

Sheet KRAFTXL

Sheet KXL Guide

Sheet Start
C2: School Name: | D2: SAMPLE SCHOOL
F3: #VALUE!
C4: Grade: | D4: 6
C6: Header: | D6: TERMINAL REPORT (JHS)
C8: Academic Year: | D8: 2024/2025
C10: Term | D10: Total Attendance | E10: Vacation Date | F10: Resume Date
C11: 1st | D11: 54 | E11: 45303 | F11: 45658
C12: 2nd | D12: 53 | E12: 30/03/2025 | F12: 45662
C13: 3rd | D13: 55 | E13: 30/08/2025 | F13: 45667

Sheet Term 1 Summary Sheet
A1: TERM 1 TEACHER'S SUMMARY SHEET
A2: ID# | B2: STUDENT NAME | C2: MATHEMATICS | G2: ENGLISH LANGUAGE | K2: SOCIAL STUDIES | O2: INTEGRATED SCIENCE | S2: CREATIVE ARTS | W2: CAREER TECHNOLOGY | AA2: COMPUTING | AE2: RELIGIOUS & MORAL EDUCATION | AI2: FRENCH | AM2: GHANAIAN LANGUAGE (TWI) | AQ2: HIGH SCORE | AR2: RANK | AS2: ATTENDANCE | AT2: CONDUCT | AU2: LEARNERS INTEREST | AV2: CLASS FACILITATOR'S REMARKS
C3: CS | D3: ES | E3: TL | F3: PN | G3: CS | H3: ES | I3: TL | J3: PN | K3: CS | L3: ES | M3: TL | N3: PN | O3: CS | P3: ES | Q3: TL | R3: PN | S3: CS | T3: ES | U3: TL | V3: PN | W3: CS | X3: ES | Y3: TL | Z3: PN | AA3: CS | AB3: ES | AC3: TL | AD3: PN | AE3: CS | AF3: ES | AG3: TL | AH3: PN | AI3: CS | AJ3: ES | AK3: TL | AL3: PN | AM3: CS | AN3: ES | AO3: TL | AP3: PN
A5: P001 | B5: Benjamin Jackson | C5: ='[1]Term 1'!$N$5 -> 38.5 | D5: ='[1]Term 1'!$P5 -> 47.5 | E5: =SUM(C5,D5) -> 86 | F5: =_xlfn.RANK.EQ(E5,$E$5:$E$104,) -> 1 | G5: ='[2]Term 1'!$N$5 -> 0 | H5: ='[2]Term 1'!$P$5 -> 0 | I5: =SUM(G5,H5) -> 0 | J5: =_xlfn.RANK.EQ(I5,$I$5:$I$104,) -> 1 | K5: ='[3]Term 1'!$N$5 -> 0 | L5: ='[3]Term 1'!$P$5 -> 0 | M5: =SUM(K5,L5) -> 0 | N5: =_xlfn.RANK.EQ(M5,$M$5:$M$104,) -> 1 | O5: ='[4]Term 1'!$N$5 -> 0 | P5: ='[4]Term 1'!$P$5 -> 0 | Q5: =SUM(O5,P5) -> 0 | R5: =_xlfn.RANK.EQ(Q5,$Q$5:$Q$104,) -> 1 | S5: ='[5]Term 1'!$N$5 -> 0 | T5: ='[5]Term 1'!$P$5 -> 0 | U5: =SUM(S5,T5) -> 0 | V5: =_xlfn.RANK.EQ(U5,$U$5:$U$104,) -> 1 | W5: ='[6]Term 1'!$N$5 -> 0 | X5: ='[6]Term 1'!$P$5 -> 0 | Y5: =SUM(W5,X5) -> 0 | Z5: =_xlfn.RANK.EQ(Y5,$Y$5:$Y$104,) -> 1 | AA5: ='[7]Term 1'!$N$5 -> 0 | AB5: ='[7]Term 1'!$P$5 -> 0 | AC5: =SUM(AA5,AB5) -> 0 | AD5: =_xlfn.RANK.EQ(AC5,$AC$5:$AC$104,) -> 1 | AE5: ='[8]Term 1'!$N$5 -> 0 | AF5: ='[8]Term 1'!$P$5 -> 0 | AG5: =SUM(AE5,AF5) -> 0 | AH5: =_xlfn.RANK.EQ(AG5,$AG$5:$AG$104,) -> 1 | AI5: ='[9]Term 1'!$N$5 -> 0 | AJ5: ='[9]Term 1'!$P$5 -> 0 | AK5: =SUM(AI5,AJ5) -> 0 | AL5: =_xlfn.RANK.EQ(AK5,$AK$5:$AK$104,) -> 1 | AM5: ='[10]Term 1'!$N$5 -> 0 | AN5: ='[10]Term 1'!$P$5 -> 0 | AO5: =SUM(AM5,AN5) -> 0 | AP5: =_xlfn.RANK.EQ(AO5,$AO$5:$AO$104,) -> 1 | AQ5: =SUM(E5,I5,M5,Q5,U5,Y5,AC5,AG5,AK5,AO5) -> 86 | AR5: =_xlfn.RANK.EQ(AQ5,$AQ$5:$AQ$104,) -> 1 | AS5: ±
A6: P002 | B6: Henry Franklin | C6: ='[1]Term 1'!$N$6 -> 34 | D6: ='[1]Term 1'!$P6 -> 48 | E6: =SUM(C6,D6) -> 82 | F6: =_xlfn.RANK.EQ(E6,$E$5:$E$104,) -> 3 | G6: ='[2]Term 1'!$N$6 -> 0 | H6: ='[2]Term 1'!$P$6 -> 0 | I6: =SUM(G6,H6) -> 0 | J6: =_xlfn.RANK.EQ(I6,$I$5:$I$104,) -> 1 | K6: ='[3]Term 1'!$N$6 -> 0 | L6: ='[3]Term 1'!$P$6 -> 0 | M6: =SUM(K6,L6) -> 0 | N6: =_xlfn.RANK.EQ(M6,$M$5:$M$104,) -> 1 | O6: ='[4]Term 1'!$N$6 -> 0 | P6: ='[4]Term 1'!$P$6 -> 0 | Q6: =SUM(O6,P6) -> 0 | R6: =_xlfn.RANK.EQ(Q6,$Q$5:$Q$104,) -> 1 | S6: ='[5]Term 1'!$N$6 -> 0 | T6: ='[5]Term 1'!$P$6 -> 0 | U6: =SUM(S6,T6) -> 0 | V6: =_xlfn.RANK.EQ(U6,$U$5:$U$104,) -> 1 | W6: ='[6]Term 1'!$N$6 -> 0 | X6: ='[6]Term 1'!$P$6 -> 0 | Y6: =SUM(W6,X6) -> 0 | Z6: =_xlfn.RANK.EQ(Y6,$Y$5:$Y$104,) -> 1 | AA6: ='[7]Term 1'!$N$6 -> 0 | AB6: ='[7]Term 1'!$P$6 -> 0 | AC6: =SUM(AA6,AB6) -> 0 | AD6: =_xlfn.RANK.EQ(AC6,$AC$5:$AC$104,) -> 1 | AE6: ='[8]Term 1'!$N$6 -> 0 | AF6: ='[8]Term 1'!$P$6 -> 0 | AG6: =SUM(AE6,AF6) -> 0 | AH6: =_xlfn.RANK.EQ(AG6,$AG$5:$AG$104,) -> 1 | AI6: ='[9]Term 1'!$N$6 -> 0 | AJ6: ='[9]Term 1'!$P$6 -> 0 | AK6: =SUM(AI6,AJ6) -> 0 | AL6: =_xlfn.RANK.EQ(AK6,$AK$5:$AK$104,) -> 1 | AM6: ='[10]Term 1'!$N$6 -> 0 | AN6: ='[10]Term 1'!$P$6 -> 0 | AO6: =SUM(AM6,AN6) -> 0 | AP6: =_xlfn.RANK.EQ(AO6,$AO$5:$AO$104,) -> 1 | AQ6: =SUM(E6,I6,M6,Q6,U6,Y6,AC6,AG6,AK6,AO6) -> 82 | AR6: =_xlfn.RANK.EQ(AQ6,$AQ$5:$AQ$104,) -> 3 | AS6: ±
A7: P003 | B7: Lily Moore | C7: ='[1]Term 1'!$N$7 -> 36 | D7: ='[1]Term 1'!$P7 -> 48 | E7: =SUM(C7,D7) -> 84 | F7: =_xlfn.RANK.EQ(E7,$E$5:$E$104,) -> 2 | G7: ='[2]Term 1'!$N$7 -> 0 | H7: ='[2]Term 1'!$P$7 -> 0 | I7: =SUM(G7,H7) -> 0 | J7: =_xlfn.RANK.EQ(I7,$I$5:$I$104,) -> 1 | K7: ='[3]Term 1'!$N$7 -> 0 | L7: ='[3]Term 1'!$P$7 -> 0 | M7: =SUM(K7,L7) -> 0 | N7: =_xlfn.RANK.EQ(M7,$M$5:$M$104,) -> 1 | O7: ='[4]Term 1'!$N$7 -> 0 | P7: ='[4]Term 1'!$P$7 -> 0 | Q7: =SUM(O7,P7) -> 0 | R7: =_xlfn.RANK.EQ(Q7,$Q$5:$Q$104,) -> 1 | S7: ='[5]Term 1'!$N$7 -> 0 | T7: ='[5]Term 1'!$P$7 -> 0 | U7: =SUM(S7,T7) -> 0 | V7: =_xlfn.RANK.EQ(U7,$U$5:$U$104,) -> 1 | W7: ='[6]Term 1'!$N$7 -> 0 | X7: ='[6]Term 1'!$P$7 -> 0 | Y7: =SUM(W7,X7) -> 0 | Z7: =_xlfn.RANK.EQ(Y7,$Y$5:$Y$104,) -> 1 | AA7: ='[7]Term 1'!$N$7 -> 0 | AB7: ='[7]Term 1'!$P$7 -> 0 | AC7: =SUM(AA7,AB7) -> 0 | AD7: =_xlfn.RANK.EQ(AC7,$AC$5:$AC$104,) -> 1 | AE7: ='[8]Term 1'!$N$7 -> 0 | AF7: ='[8]Term 1'!$P$7 -> 0 | AG7: =SUM(AE7,AF7) -> 0 | AH7: =_xlfn.RANK.EQ(AG7,$AG$5:$AG$104,) -> 1 | AI7: ='[9]Term 1'!$N$7 -> 0 | AJ7: ='[9]Term 1'!$P$7 -> 0 | AK7: =SUM(AI7,AJ7) -> 0 | AL7: =_xlfn.RANK.EQ(AK7,$AK$5:$AK$104,) -> 1 | AM7: ='[10]Term 1'!$N$7 -> 0 | AN7: ='[10]Term 1'!$P$7 -> 0 | AO7: =SUM(AM7,AN7) -> 0 | AP7: =_xlfn.RANK.EQ(AO7,$AO$5:$AO$104,) -> 1 | AQ7: =SUM(E7,I7,M7,Q7,U7,Y7,AC7,AG7,AK7,AO7) -> 84 | AR7: =_xlfn.RANK.EQ(AQ7,$AQ$5:$AQ$104,) -> 2 | AS7: ±
A8: P004 | C8: ='[1]Term 1'!$N$8 -> 0 | D8: ='[1]Term 1'!$P8 -> 0 | E8: =SUM(C8,D8) -> 0 | F8: =_xlfn.RANK.EQ(E8,$E$5:$E$104,) -> 4 | G8: ='[2]Term 1'!$N$8 -> 0 | H8: ='[2]Term 1'!$P$8 -> 0 | I8: =SUM(G8,H8) -> 0 | J8: =_xlfn.RANK.EQ(I8,$I$5:$I$104,) -> 1 | K8: ='[3]Term 1'!$N$8 -> 0 | L8: ='[3]Term 1'!$P$8 -> 0 | M8: =SUM(K8,L8) -> 0 | N8: =_xlfn.RANK.EQ(M8,$M$5:$M$104,) -> 1 | O8: ='[4]Term 1'!$N$8 -> 0 | P8: ='[4]Term 1'!$P$8 -> 0 | Q8: =SUM(O8,P8) -> 0 | R8: =_xlfn.RANK.EQ(Q8,$Q$5:$Q$104,) -> 1 | S8: ='[5]Term 1'!$N$8 -> 0 | T8: ='[5]Term 1'!$P$8 -> 0 | U8: =SUM(S8,T8) -> 0 | V8: =_xlfn.RANK.EQ(U8,$U$5:$U$104,) -> 1 | W8: ='[6]Term 1'!$N$8 -> 0 | X8: ='[6]Term 1'!$P$8 -> 0 | Y8: =SUM(W8,X8) -> 0 | Z8: =_xlfn.RANK.EQ(Y8,$Y$5:$Y$104,) -> 1 | AA8: ='[7]Term 1'!$N$8 -> 0 | AB8: ='[7]Term 1'!$P$8 -> 0 | AC8: =SUM(AA8,AB8) -> 0 | AD8: =_xlfn.RANK.EQ(AC8,$AC$5:$AC$104,) -> 1 | AE8: ='[8]Term 1'!$N$8 -> 0 | AF8: ='[8]Term 1'!$P$8 -> 0 | AG8: =SUM(AE8,AF8) -> 0 | AH8: =_xlfn.RANK.EQ(AG8,$AG$5:$AG$104,) -> 1 | AI8: ='[9]Term 1'!$N$8 -> 0 | AJ8: ='[9]Term 1'!$P$8 -> 0 | AK8: =SUM(AI8,AJ8) -> 0 | AL8: =_xlfn.RANK.EQ(AK8,$AK$5:$AK$104,) -> 1 | AM8: ='[10]Term 1'!$N$8 -> 0 | AN8: ='[10]Term 1'!$P$8 -> 0 | AO8: =SUM(AM8,AN8) -> 0 | AP8: =_xlfn.RANK.EQ(AO8,$AO$5:$AO$104,) -> 1 | AQ8: =SUM(E8,I8,M8,Q8,U8,Y8,AC8,AG8,AK8,AO8) -> 0 | AR8: =_xlfn.RANK.EQ(AQ8,$AQ$5:$AQ$104,) -> 4 | AS8: ±
A9: P005 | C9: ='[1]Term 1'!$N$9 -> 0 | D9: ='[1]Term 1'!$P9 -> 0 | E9: =SUM(C9,D9) -> 0 | F9: =_xlfn.RANK.EQ(E9,$E$5:$E$104,) -> 4 | G9: ='[2]Term 1'!$N$9 -> 0 | H9: ='[2]Term 1'!$P$9 -> 0 | I9: =SUM(G9,H9) -> 0 | J9: =_xlfn.RANK.EQ(I9,$I$5:$I$104,) -> 1 | K9: ='[3]Term 1'!$N$9 -> 0 | L9: ='[3]Term 1'!$P$9 -> 0 | M9: =SUM(K9,L9) -> 0 | N9: =_xlfn.RANK.EQ(M9,$M$5:$M$104,) -> 1 | O9: ='[4]Term 1'!$N$9 -> 0 | P9: ='[4]Term 1'!$P$9 -> 0 | Q9: =SUM(O9,P9) -> 0 | R9: =_xlfn.RANK.EQ(Q9,$Q$5:$Q$104,) -> 1 | S9: ='[5]Term 1'!$N$9 -> 0 | T9: ='[5]Term 1'!$P$9 -> 0 | U9: =SUM(S9,T9) -> 0 | V9: =_xlfn.RANK.EQ(U9,$U$5:$U$104,) -> 1 | W9: ='[6]Term 1'!$N$9 -> 0 | X9: ='[6]Term 1'!$P$9 -> 0 | Y9: =SUM(W9,X9) -> 0 | Z9: =_xlfn.RANK.EQ(Y9,$Y$5:$Y$104,) -> 1 | AA9: ='[7]Term 1'!$N$9 -> 0 | AB9: ='[7]Term 1'!$P$9 -> 0 | AC9: =SUM(AA9,AB9) -> 0 | AD9: =_xlfn.RANK.EQ(AC9,$AC$5:$AC$104,) -> 1 | AE9: ='[8]Term 1'!$N$9 -> 0 | AF9: ='[8]Term 1'!$P$9 -> 0 | AG9: =SUM(AE9,AF9) -> 0 | AH9: =_xlfn.RANK.EQ(AG9,$AG$5:$AG$104,) -> 1 | AI9: ='[9]Term 1'!$N$9 -> 0 | AJ9: ='[9]Term 1'!$P$9 -> 0 | AK9: =SUM(AI9,AJ9) -> 0 | AL9: =_xlfn.RANK.EQ(AK9,$AK$5:$AK$104,) -> 1 | AM9: ='[10]Term 1'!$N$9 -> 0 | AN9: ='[10]Term 1'!$P$9 -> 0 | AO9: =SUM(AM9,AN9) -> 0 | AP9: =_xlfn.RANK.EQ(AO9,$AO$5:$AO$104,) -> 1 | AQ9: =SUM(E9,I9,M9,Q9,U9,Y9,AC9,AG9,AK9,AO9) -> 0 | AR9: =_xlfn.RANK.EQ(AQ9,$AQ$5:$AQ$104,) -> 4 | AS9: ±
A10: P006 | C10: ='[1]Term 1'!$N$10 -> 0 | D10: ='[1]Term 1'!$P10 -> 0 | E10: =SUM(C10,D10) -> 0 | F10: =_xlfn.RANK.EQ(E10,$E$5:$E$104,) -> 4 | G10: ='[2]Term 1'!$N$10 -> 0 | H10: ='[2]Term 1'!$P$10 -> 0 | I10: =SUM(G10,H10) -> 0 | J10: =_xlfn.RANK.EQ(I10,$I$5:$I$104,) -> 1 | K10: ='[3]Term 1'!$N$10 -> 0 | L10: ='[3]Term 1'!$P$10 -> 0 | M10: =SUM(K10,L10) -> 0 | N10: =_xlfn.RANK.EQ(M10,$M$5:$M$104,) -> 1 | O10: ='[4]Term 1'!$N$10 -> 0 | P10: ='[4]Term 1'!$P$10 -> 0 | Q10: =SUM(O10,P10) -> 0 | R10: =_xlfn.RANK.EQ(Q10,$Q$5:$Q$104,) -> 1 | S10: ='[5]Term 1'!$N$10 -> 0 | T10: ='[5]Term 1'!$P$10 -> 0 | U10: =SUM(S10,T10) -> 0 | V10: =_xlfn.RANK.EQ(U10,$U$5:$U$104,) -> 1 | W10: ='[6]Term 1'!$N$10 -> 0 | X10: ='[6]Term 1'!$P$10 -> 0 | Y10: =SUM(W10,X10) -> 0 | Z10: =_xlfn.RANK.EQ(Y10,$Y$5:$Y$104,) -> 1 | AA10: ='[7]Term 1'!$N$10 -> 0 | AB10: ='[7]Term 1'!$P$10 -> 0 | AC10: =SUM(AA10,AB10) -> 0 | AD10: =_xlfn.RANK.EQ(AC10,$AC$5:$AC$104,) -> 1 | AE10: ='[8]Term 1'!$N$10 -> 0 | AF10: ='[8]Term 1'!$P$10 -> 0 | AG10: =SUM(AE10,AF10) -> 0 | AH10: =_xlfn.RANK.EQ(AG10,$AG$5:$AG$104,) -> 1 | AI10: ='[9]Term 1'!$N$10 -> 0 | AJ10: ='[9]Term 1'!$P$10 -> 0 | AK10: =SUM(AI10,AJ10) -> 0 | AL10: =_xlfn.RANK.EQ(AK10,$AK$5:$AK$104,) -> 1 | AM10: ='[10]Term 1'!$N$10 -> 0 | AN10: ='[10]Term 1'!$P$10 -> 0 | AO10: =SUM(AM10,AN10) -> 0 | AP10: =_xlfn.RANK.EQ(AO10,$AO$5:$AO$104,) -> 1 | AQ10: =SUM(E10,I10,M10,Q10,U10,Y10,AC10,AG10,AK10,AO10) -> 0 | AR10: =_xlfn.RANK.EQ(AQ10,$AQ$5:$AQ$104,) -> 4 | AS10: ±
A11: P007 | C11: ='[1]Term 1'!$N$11 -> 0 | D11: ='[1]Term 1'!$P11 -> 0 | E11: =SUM(C11,D11) -> 0 | F11: =_xlfn.RANK.EQ(E11,$E$5:$E$104,) -> 4 | G11: ='[2]Term 1'!$N$11 -> 0 | H11: ='[2]Term 1'!$P$11 -> 0 | I11: =SUM(G11,H11) -> 0 | J11: =_xlfn.RANK.EQ(I11,$I$5:$I$104,) -> 1 | K11: ='[3]Term 1'!$N$11 -> 0 | L11: ='[3]Term 1'!$P$11 -> 0 | M11: =SUM(K11,L11) -> 0 | N11: =_xlfn.RANK.EQ(M11,$M$5:$M$104,) -> 1 | O11: ='[4]Term 1'!$N$11 -> 0 | P11: ='[4]Term 1'!$P$11 -> 0 | Q11: =SUM(O11,P11) -> 0 | R11: =_xlfn.RANK.EQ(Q11,$Q$5:$Q$104,) -> 1 | S11: ='[5]Term 1'!$N$11 -> 0 | T11: ='[5]Term 1'!$P$11 -> 0 | U11: =SUM(S11,T11) -> 0 | V11: =_xlfn.RANK.EQ(U11,$U$5:$U$104,) -> 1 | W11: ='[6]Term 1'!$N$11 -> 0 | X11: ='[6]Term 1'!$P$11 -> 0 | Y11: =SUM(W11,X11) -> 0 | Z11: =_xlfn.RANK.EQ(Y11,$Y$5:$Y$104,) -> 1 | AA11: ='[7]Term 1'!$N$11 -> 0 | AB11: ='[7]Term 1'!$P$11 -> 0 | AC11: =SUM(AA11,AB11) -> 0 | AD11: =_xlfn.RANK.EQ(AC11,$AC$5:$AC$104,) -> 1 | AE11: ='[8]Term 1'!$N$11 -> 0 | AF11: ='[8]Term 1'!$P$11 -> 0 | AG11: =SUM(AE11,AF11) -> 0 | AH11: =_xlfn.RANK.EQ(AG11,$AG$5:$AG$104,) -> 1 | AI11: ='[9]Term 1'!$N$11 -> 0 | AJ11: ='[9]Term 1'!$P$11 -> 0 | AK11: =SUM(AI11,AJ11) -> 0 | AL11: =_xlfn.RANK.EQ(AK11,$AK$5:$AK$104,) -> 1 | AM11: ='[10]Term 1'!$N$11 -> 0 | AN11: ='[10]Term 1'!$P$11 -> 0 | AO11: =SUM(AM11,AN11) -> 0 | AP11: =_xlfn.RANK.EQ(AO11,$AO$5:$AO$104,) -> 1 | AQ11: =SUM(E11,I11,M11,Q11,U11,Y11,AC11,AG11,AK11,AO11) -> 0 | AR11: =_xlfn.RANK.EQ(AQ11,$AQ$5:$AQ$104,) -> 4 | AS11: ±
A12: P008 | C12: ='[1]Term 1'!$N$12 -> 0 | D12: ='[1]Term 1'!$P12 -> 0 | E12: =SUM(C12,D12) -> 0 | F12: =_xlfn.RANK.EQ(E12,$E$5:$E$104,) -> 4 | G12: ='[2]Term 1'!$N$12 -> 0 | H12: ='[2]Term 1'!$P$12 -> 0 | I12: =SUM(G12,H12) -> 0 | J12: =_xlfn.RANK.EQ(I12,$I$5:$I$104,) -> 1 | K12: ='[3]Term 1'!$N$12 -> 0 | L12: ='[3]Term 1'!$P$12 -> 0 | M12: =SUM(K12,L12) -> 0 | N12: =_xlfn.RANK.EQ(M12,$M$5:$M$104,) -> 1 | O12: ='[4]Term 1'!$N$12 -> 0 | P12: ='[4]Term 1'!$P$12 -> 0 | Q12: =SUM(O12,P12) -> 0 | R12: =_xlfn.RANK.EQ(Q12,$Q$5:$Q$104,) -> 1 | S12: ='[5]Term 1'!$N$12 -> 0 | T12: ='[5]Term 1'!$P$12 -> 0 | U12: =SUM(S12,T12) -> 0 | V12: =_xlfn.RANK.EQ(U12,$U$5:$U$104,) -> 1 | W12: ='[6]Term 1'!$N$12 -> 0 | X12: ='[6]Term 1'!$P$12 -> 0 | Y12: =SUM(W12,X12) -> 0 | Z12: =_xlfn.RANK.EQ(Y12,$Y$5:$Y$104,) -> 1 | AA12: ='[7]Term 1'!$N$12 -> 0 | AB12: ='[7]Term 1'!$P$12 -> 0 | AC12: =SUM(AA12,AB12) -> 0 | AD12: =_xlfn.RANK.EQ(AC12,$AC$5:$AC$104,) -> 1 | AE12: ='[8]Term 1'!$N$12 -> 0 | AF12: ='[8]Term 1'!$P$12 -> 0 | AG12: =SUM(AE12,AF12) -> 0 | AH12: =_xlfn.RANK.EQ(AG12,$AG$5:$AG$104,) -> 1 | AI12: ='[9]Term 1'!$N$12 -> 0 | AJ12: ='[9]Term 1'!$P$12 -> 0 | AK12: =SUM(AI12,AJ12) -> 0 | AL12: =_xlfn.RANK.EQ(AK12,$AK$5:$AK$104,) -> 1 | AM12: ='[10]Term 1'!$N$12 -> 0 | AN12: ='[10]Term 1'!$P$12 -> 0 | AO12: =SUM(AM12,AN12) -> 0 | AP12: =_xlfn.RANK.EQ(AO12,$AO$5:$AO$104,) -> 1 | AQ12: =SUM(E12,I12,M12,Q12,U12,Y12,AC12,AG12,AK12,AO12) -> 0 | AR12: =_xlfn.RANK.EQ(AQ12,$AQ$5:$AQ$104,) -> 4 | AS12: ±
A13: P009 | C13: ='[1]Term 1'!$N$13 -> 0 | D13: ='[1]Term 1'!$P13 -> 0 | E13: =SUM(C13,D13) -> 0 | F13: =_xlfn.RANK.EQ(E13,$E$5:$E$104,) -> 4 | G13: ='[2]Term 1'!$N$13 -> 0 | H13: ='[2]Term 1'!$P$13 -> 0 | I13: =SUM(G13,H13) -> 0 | J13: =_xlfn.RANK.EQ(I13,$I$5:$I$104,) -> 1 | K13: ='[3]Term 1'!$N$13 -> 0 | L13: ='[3]Term 1'!$P$13 -> 0 | M13: =SUM(K13,L13) -> 0 | N13: =_xlfn.RANK.EQ(M13,$M$5:$M$104,) -> 1 | O13: ='[4]Term 1'!$N$13 -> 0 | P13: ='[4]Term 1'!$P$13 -> 0 | Q13: =SUM(O13,P13) -> 0 | R13: =_xlfn.RANK.EQ(Q13,$Q$5:$Q$104,) -> 1 | S13: ='[5]Term 1'!$N$13 -> 0 | T13: ='[5]Term 1'!$P$13 -> 0 | U13: =SUM(S13,T13) -> 0 | V13: =_xlfn.RANK.EQ(U13,$U$5:$U$104,) -> 1 | W13: ='[6]Term 1'!$N$13 -> 0 | X13: ='[6]Term 1'!$P$13 -> 0 | Y13: =SUM(W13,X13) -> 0 | Z13: =_xlfn.RANK.EQ(Y13,$Y$5:$Y$104,) -> 1 | AA13: ='[7]Term 1'!$N$13 -> 0 | AB13: ='[7]Term 1'!$P$13 -> 0 | AC13: =SUM(AA13,AB13) -> 0 | AD13: =_xlfn.RANK.EQ(AC13,$AC$5:$AC$104,) -> 1 | AE13: ='[8]Term 1'!$N$13 -> 0 | AF13: ='[8]Term 1'!$P$13 -> 0 | AG13: =SUM(AE13,AF13) -> 0 | AH13: =_xlfn.RANK.EQ(AG13,$AG$5:$AG$104,) -> 1 | AI13: ='[9]Term 1'!$N$13 -> 0 | AJ13: ='[9]Term 1'!$P$13 -> 0 | AK13: =SUM(AI13,AJ13) -> 0 | AL13: =_xlfn.RANK.EQ(AK13,$AK$5:$AK$104,) -> 1 | AM13: ='[10]Term 1'!$N$13 -> 0 | AN13: ='[10]Term 1'!$P$13 -> 0 | AO13: =SUM(AM13,AN13) -> 0 | AP13: =_xlfn.RANK.EQ(AO13,$AO$5:$AO$104,) -> 1 | AQ13: =SUM(E13,I13,M13,Q13,U13,Y13,AC13,AG13,AK13,AO13) -> 0 | AR13: =_xlfn.RANK.EQ(AQ13,$AQ$5:$AQ$104,) -> 4 | AS13: ±
A14: P010 | C14: ='[1]Term 1'!$N$14 -> 0 | D14: ='[1]Term 1'!$P14 -> 0 | E14: =SUM(C14,D14) -> 0 | F14: =_xlfn.RANK.EQ(E14,$E$5:$E$104,) -> 4 | G14: ='[2]Term 1'!$N$14 -> 0 | H14: ='[2]Term 1'!$P$14 -> 0 | I14: =SUM(G14,H14) -> 0 | J14: =_xlfn.RANK.EQ(I14,$I$5:$I$104,) -> 1 | K14: ='[3]Term 1'!$N$14 -> 0 | L14: ='[3]Term 1'!$P$14 -> 0 | M14: =SUM(K14,L14) -> 0 | N14: =_xlfn.RANK.EQ(M14,$M$5:$M$104,) -> 1 | O14: ='[4]Term 1'!$N$14 -> 0 | P14: ='[4]Term 1'!$P$14 -> 0 | Q14: =SUM(O14,P14) -> 0 | R14: =_xlfn.RANK.EQ(Q14,$Q$5:$Q$104,) -> 1 | S14: ='[5]Term 1'!$N$14 -> 0 | T14: ='[5]Term 1'!$P$14 -> 0 | U14: =SUM(S14,T14) -> 0 | V14: =_xlfn.RANK.EQ(U14,$U$5:$U$104,) -> 1 | W14: ='[6]Term 1'!$N$14 -> 0 | X14: ='[6]Term 1'!$P$14 -> 0 | Y14: =SUM(W14,X14) -> 0 | Z14: =_xlfn.RANK.EQ(Y14,$Y$5:$Y$104,) -> 1 | AA14: ='[7]Term 1'!$N$14 -> 0 | AB14: ='[7]Term 1'!$P$14 -> 0 | AC14: =SUM(AA14,AB14) -> 0 | AD14: =_xlfn.RANK.EQ(AC14,$AC$5:$AC$104,) -> 1 | AE14: ='[8]Term 1'!$N$14 -> 0 | AF14: ='[8]Term 1'!$P$14 -> 0 | AG14: =SUM(AE14,AF14) -> 0 | AH14: =_xlfn.RANK.EQ(AG14,$AG$5:$AG$104,) -> 1 | AI14: ='[9]Term 1'!$N$14 -> 0 | AJ14: ='[9]Term 1'!$P$14 -> 0 | AK14: =SUM(AI14,AJ14) -> 0 | AL14: =_xlfn.RANK.EQ(AK14,$AK$5:$AK$104,) -> 1 | AM14: ='[10]Term 1'!$N$14 -> 0 | AN14: ='[10]Term 1'!$P$14 -> 0 | AO14: =SUM(AM14,AN14) -> 0 | AP14: =_xlfn.RANK.EQ(AO14,$AO$5:$AO$104,) -> 1 | AQ14: =SUM(E14,I14,M14,Q14,U14,Y14,AC14,AG14,AK14,AO14) -> 0 | AR14: =_xlfn.RANK.EQ(AQ14,$AQ$5:$AQ$104,) -> 4 | AS14: ±
A15: P011 | C15: ='[1]Term 1'!$N$15 -> 0 | D15: ='[1]Term 1'!$P15 -> 0 | E15: =SUM(C15,D15) -> 0 | F15: =_xlfn.RANK.EQ(E15,$E$5:$E$104,) -> 4 | G15: ='[2]Term 1'!$N$15 -> 0 | H15: ='[2]Term 1'!$P$15 -> 0 | I15: =SUM(G15,H15) -> 0 | J15: =_xlfn.RANK.EQ(I15,$I$5:$I$104,) -> 1 | K15: ='[3]Term 1'!$N$15 -> 0 | L15: ='[3]Term 1'!$P$15 -> 0 | M15: =SUM(K15,L15) -> 0 | N15: =_xlfn.RANK.EQ(M15,$M$5:$M$104,) -> 1 | O15: ='[4]Term 1'!$N$15 -> 0 | P15: ='[4]Term 1'!$P$15 -> 0 | Q15: =SUM(O15,P15) -> 0 | R15: =_xlfn.RANK.EQ(Q15,$Q$5:$Q$104,) -> 1 | S15: ='[5]Term 1'!$N$15 -> 0 | T15: ='[5]Term 1'!$P$15 -> 0 | U15: =SUM(S15,T15) -> 0 | V15: =_xlfn.RANK.EQ(U15,$U$5:$U$104,) -> 1 | W15: ='[6]Term 1'!$N$15 -> 0 | X15: ='[6]Term 1'!$P$15 -> 0 | Y15: =SUM(W15,X15) -> 0 | Z15: =_xlfn.RANK.EQ(Y15,$Y$5:$Y$104,) -> 1 | AA15: ='[7]Term 1'!$N$15 -> 0 | AB15: ='[7]Term 1'!$P$15 -> 0 | AC15: =SUM(AA15,AB15) -> 0 | AD15: =_xlfn.RANK.EQ(AC15,$AC$5:$AC$104,) -> 1 | AE15: ='[8]Term 1'!$N$15 -> 0 | AF15: ='[8]Term 1'!$P$15 -> 0 | AG15: =SUM(AE15,AF15) -> 0 | AH15: =_xlfn.RANK.EQ(AG15,$AG$5:$AG$104,) -> 1 | AI15: ='[9]Term 1'!$N$15 -> 0 | AJ15: ='[9]Term 1'!$P$15 -> 0 | AK15: =SUM(AI15,AJ15) -> 0 | AL15: =_xlfn.RANK.EQ(AK15,$AK$5:$AK$104,) -> 1 | AM15: ='[10]Term 1'!$N$15 -> 0 | AN15: ='[10]Term 1'!$P$15 -> 0 | AO15: =SUM(AM15,AN15) -> 0 | AP15: =_xlfn.RANK.EQ(AO15,$AO$5:$AO$104,) -> 1 | AQ15: =SUM(E15,I15,M15,Q15,U15,Y15,AC15,AG15,AK15,AO15) -> 0 | AR15: =_xlfn.RANK.EQ(AQ15,$AQ$5:$AQ$104,) -> 4 | AS15: ±
A16: P012 | C16: ='[1]Term 1'!$N$16 -> 0 | D16: ='[1]Term 1'!$P16 -> 0 | E16: =SUM(C16,D16) -> 0 | F16: =_xlfn.RANK.EQ(E16,$E$5:$E$104,) -> 4 | G16: ='[2]Term 1'!$N$16 -> 0 | H16: ='[2]Term 1'!$P$16 -> 0 | I16: =SUM(G16,H16) -> 0 | J16: =_xlfn.RANK.EQ(I16,$I$5:$I$104,) -> 1 | K16: ='[3]Term 1'!$N$16 -> 0 | L16: ='[3]Term 1'!$P$16 -> 0 | M16: =SUM(K16,L16) -> 0 | N16: =_xlfn.RANK.EQ(M16,$M$5:$M$104,) -> 1 | O16: ='[4]Term 1'!$N$16 -> 0 | P16: ='[4]Term 1'!$P$16 -> 0 | Q16: =SUM(O16,P16) -> 0 | R16: =_xlfn.RANK.EQ(Q16,$Q$5:$Q$104,) -> 1 | S16: ='[5]Term 1'!$N$16 -> 0 | T16: ='[5]Term 1'!$P$16 -> 0 | U16: =SUM(S16,T16) -> 0 | V16: =_xlfn.RANK.EQ(U16,$U$5:$U$104,) -> 1 | W16: ='[6]Term 1'!$N$16 -> 0 | X16: ='[6]Term 1'!$P$16 -> 0 | Y16: =SUM(W16,X16) -> 0 | Z16: =_xlfn.RANK.EQ(Y16,$Y$5:$Y$104,) -> 1 | AA16: ='[7]Term 1'!$N$16 -> 0 | AB16: ='[7]Term 1'!$P$16 -> 0 | AC16: =SUM(AA16,AB16) -> 0 | AD16: =_xlfn.RANK.EQ(AC16,$AC$5:$AC$104,) -> 1 | AE16: ='[8]Term 1'!$N$16 -> 0 | AF16: ='[8]Term 1'!$P$16 -> 0 | AG16: =SUM(AE16,AF16) -> 0 | AH16: =_xlfn.RANK.EQ(AG16,$AG$5:$AG$104,) -> 1 | AI16: ='[9]Term 1'!$N$16 -> 0 | AJ16: ='[9]Term 1'!$P$16 -> 0 | AK16: =SUM(AI16,AJ16) -> 0 | AL16: =_xlfn.RANK.EQ(AK16,$AK$5:$AK$104,) -> 1 | AM16: ='[10]Term 1'!$N$16 -> 0 | AN16: ='[10]Term 1'!$P$16 -> 0 | AO16: =SUM(AM16,AN16) -> 0 | AP16: =_xlfn.RANK.EQ(AO16,$AO$5:$AO$104,) -> 1 | AQ16: =SUM(E16,I16,M16,Q16,U16,Y16,AC16,AG16,AK16,AO16) -> 0 | AR16: =_xlfn.RANK.EQ(AQ16,$AQ$5:$AQ$104,) -> 4 | AS16: ±
A17: P013 | C17: ='[1]Term 1'!$N$17 -> 0 | D17: ='[1]Term 1'!$P17 -> 0 | E17: =SUM(C17,D17) -> 0 | F17: =_xlfn.RANK.EQ(E17,$E$5:$E$104,) -> 4 | G17: ='[2]Term 1'!$N$17 -> 0 | H17: ='[2]Term 1'!$P$17 -> 0 | I17: =SUM(G17,H17) -> 0 | J17: =_xlfn.RANK.EQ(I17,$I$5:$I$104,) -> 1 | K17: ='[3]Term 1'!$N$17 -> 0 | L17: ='[3]Term 1'!$P$17 -> 0 | M17: =SUM(K17,L17) -> 0 | N17: =_xlfn.RANK.EQ(M17,$M$5:$M$104,) -> 1 | O17: ='[4]Term 1'!$N$17 -> 0 | P17: ='[4]Term 1'!$P$17 -> 0 | Q17: =SUM(O17,P17) -> 0 | R17: =_xlfn.RANK.EQ(Q17,$Q$5:$Q$104,) -> 1 | S17: ='[5]Term 1'!$N$17 -> 0 | T17: ='[5]Term 1'!$P$17 -> 0 | U17: =SUM(S17,T17) -> 0 | V17: =_xlfn.RANK.EQ(U17,$U$5:$U$104,) -> 1 | W17: ='[6]Term 1'!$N$17 -> 0 | X17: ='[6]Term 1'!$P$17 -> 0 | Y17: =SUM(W17,X17) -> 0 | Z17: =_xlfn.RANK.EQ(Y17,$Y$5:$Y$104,) -> 1 | AA17: ='[7]Term 1'!$N$17 -> 0 | AB17: ='[7]Term 1'!$P$17 -> 0 | AC17: =SUM(AA17,AB17) -> 0 | AD17: =_xlfn.RANK.EQ(AC17,$AC$5:$AC$104,) -> 1 | AE17: ='[8]Term 1'!$N$17 -> 0 | AF17: ='[8]Term 1'!$P$17 -> 0 | AG17: =SUM(AE17,AF17) -> 0 | AH17: =_xlfn.RANK.EQ(AG17,$AG$5:$AG$104,) -> 1 | AI17: ='[9]Term 1'!$N$17 -> 0 | AJ17: ='[9]Term 1'!$P$17 -> 0 | AK17: =SUM(AI17,AJ17) -> 0 | AL17: =_xlfn.RANK.EQ(AK17,$AK$5:$AK$104,) -> 1 | AM17: ='[10]Term 1'!$N$17 -> 0 | AN17: ='[10]Term 1'!$P$17 -> 0 | AO17: =SUM(AM17,AN17) -> 0 | AP17: =_xlfn.RANK.EQ(AO17,$AO$5:$AO$104,) -> 1 | AQ17: =SUM(E17,I17,M17,Q17,U17,Y17,AC17,AG17,AK17,AO17) -> 0 | AR17: =_xlfn.RANK.EQ(AQ17,$AQ$5:$AQ$104,) -> 4 | AS17: ±
A18: P014 | C18: ='[1]Term 1'!$N$18 -> 0 | D18: ='[1]Term 1'!$P18 -> 0 | E18: =SUM(C18,D18) -> 0 | F18: =_xlfn.RANK.EQ(E18,$E$5:$E$104,) -> 4 | G18: ='[2]Term 1'!$N$18 -> 0 | H18: ='[2]Term 1'!$P$18 -> 0 | I18: =SUM(G18,H18) -> 0 | J18: =_xlfn.RANK.EQ(I18,$I$5:$I$104,) -> 1 | K18: ='[3]Term 1'!$N$18 -> 0 | L18: ='[3]Term 1'!$P$18 -> 0 | M18: =SUM(K18,L18) -> 0 | N18: =_xlfn.RANK.EQ(M18,$M$5:$M$104,) -> 1 | O18: ='[4]Term 1'!$N$18 -> 0 | P18: ='[4]Term 1'!$P$18 -> 0 | Q18: =SUM(O18,P18) -> 0 | R18: =_xlfn.RANK.EQ(Q18,$Q$5:$Q$104,) -> 1 | S18: ='[5]Term 1'!$N$18 -> 0 | T18: ='[5]Term 1'!$P$18 -> 0 | U18: =SUM(S18,T18) -> 0 | V18: =_xlfn.RANK.EQ(U18,$U$5:$U$104,) -> 1 | W18: ='[6]Term 1'!$N$18 -> 0 | X18: ='[6]Term 1'!$P$18 -> 0 | Y18: =SUM(W18,X18) -> 0 | Z18: =_xlfn.RANK.EQ(Y18,$Y$5:$Y$104,) -> 1 | AA18: ='[7]Term 1'!$N$18 -> 0 | AB18: ='[7]Term 1'!$P$18 -> 0 | AC18: =SUM(AA18,AB18) -> 0 | AD18: =_xlfn.RANK.EQ(AC18,$AC$5:$AC$104,) -> 1 | AE18: ='[8]Term 1'!$N$18 -> 0 | AF18: ='[8]Term 1'!$P$18 -> 0 | AG18: =SUM(AE18,AF18) -> 0 | AH18: =_xlfn.RANK.EQ(AG18,$AG$5:$AG$104,) -> 1 | AI18: ='[9]Term 1'!$N$18 -> 0 | AJ18: ='[9]Term 1'!$P$18 -> 0 | AK18: =SUM(AI18,AJ18) -> 0 | AL18: =_xlfn.RANK.EQ(AK18,$AK$5:$AK$104,) -> 1 | AM18: ='[10]Term 1'!$N$18 -> 0 | AN18: ='[10]Term 1'!$P$18 -> 0 | AO18: =SUM(AM18,AN18) -> 0 | AP18: =_xlfn.RANK.EQ(AO18,$AO$5:$AO$104,) -> 1 | AQ18: =SUM(E18,I18,M18,Q18,U18,Y18,AC18,AG18,AK18,AO18) -> 0 | AR18: =_xlfn.RANK.EQ(AQ18,$AQ$5:$AQ$104,) -> 4 | AS18: ±
A19: P015 | C19: ='[1]Term 1'!$N$19 -> 0 | D19: ='[1]Term 1'!$P19 -> 0 | E19: =SUM(C19,D19) -> 0 | F19: =_xlfn.RANK.EQ(E19,$E$5:$E$104,) -> 4 | G19: ='[2]Term 1'!$N$19 -> 0 | H19: ='[2]Term 1'!$P$19 -> 0 | I19: =SUM(G19,H19) -> 0 | J19: =_xlfn.RANK.EQ(I19,$I$5:$I$104,) -> 1 | K19: ='[3]Term 1'!$N$19 -> 0 | L19: ='[3]Term 1'!$P$19 -> 0 | M19: =SUM(K19,L19) -> 0 | N19: =_xlfn.RANK.EQ(M19,$M$5:$M$104,) -> 1 | O19: ='[4]Term 1'!$N$19 -> 0 | P19: ='[4]Term 1'!$P$19 -> 0 | Q19: =SUM(O19,P19) -> 0 | R19: =_xlfn.RANK.EQ(Q19,$Q$5:$Q$104,) -> 1 | S19: ='[5]Term 1'!$N$19 -> 0 | T19: ='[5]Term 1'!$P$19 -> 0 | U19: =SUM(S19,T19) -> 0 | V19: =_xlfn.RANK.EQ(U19,$U$5:$U$104,) -> 1 | W19: ='[6]Term 1'!$N$19 -> 0 | X19: ='[6]Term 1'!$P$19 -> 0 | Y19: =SUM(W19,X19) -> 0 | Z19: =_xlfn.RANK.EQ(Y19,$Y$5:$Y$104,) -> 1 | AA19: ='[7]Term 1'!$N$19 -> 0 | AB19: ='[7]Term 1'!$P$19 -> 0 | AC19: =SUM(AA19,AB19) -> 0 | AD19: =_xlfn.RANK.EQ(AC19,$AC$5:$AC$104,) -> 1 | AE19: ='[8]Term 1'!$N$19 -> 0 | AF19: ='[8]Term 1'!$P$19 -> 0 | AG19: =SUM(AE19,AF19) -> 0 | AH19: =_xlfn.RANK.EQ(AG19,$AG$5:$AG$104,) -> 1 | AI19: ='[9]Term 1'!$N$19 -> 0 | AJ19: ='[9]Term 1'!$P$19 -> 0 | AK19: =SUM(AI19,AJ19) -> 0 | AL19: =_xlfn.RANK.EQ(AK19,$AK$5:$AK$104,) -> 1 | AM19: ='[10]Term 1'!$N$19 -> 0 | AN19: ='[10]Term 1'!$P$19 -> 0 | AO19: =SUM(AM19,AN19) -> 0 | AP19: =_xlfn.RANK.EQ(AO19,$AO$5:$AO$104,) -> 1 | AQ19: =SUM(E19,I19,M19,Q19,U19,Y19,AC19,AG19,AK19,AO19) -> 0 | AR19: =_xlfn.RANK.EQ(AQ19,$AQ$5:$AQ$104,) -> 4 | AS19: ±
A20: P016 | C20: ='[1]Term 1'!$N$20 -> 0 | D20: ='[1]Term 1'!$P20 -> 0 | E20: =SUM(C20,D20) -> 0 | F20: =_xlfn.RANK.EQ(E20,$E$5:$E$104,) -> 4 | G20: ='[2]Term 1'!$N$20 -> 0 | H20: ='[2]Term 1'!$P$20 -> 0 | I20: =SUM(G20,H20) -> 0 | J20: =_xlfn.RANK.EQ(I20,$I$5:$I$104,) -> 1 | K20: ='[3]Term 1'!$N$20 -> 0 | L20: ='[3]Term 1'!$P$20 -> 0 | M20: =SUM(K20,L20) -> 0 | N20: =_xlfn.RANK.EQ(M20,$M$5:$M$104,) -> 1 | O20: ='[4]Term 1'!$N$20 -> 0 | P20: ='[4]Term 1'!$P$20 -> 0 | Q20: =SUM(O20,P20) -> 0 | R20: =_xlfn.RANK.EQ(Q20,$Q$5:$Q$104,) -> 1 | S20: ='[5]Term 1'!$N$20 -> 0 | T20: ='[5]Term 1'!$P$20 -> 0 | U20: =SUM(S20,T20) -> 0 | V20: =_xlfn.RANK.EQ(U20,$U$5:$U$104,) -> 1 | W20: ='[6]Term 1'!$N$20 -> 0 | X20: ='[6]Term 1'!$P$20 -> 0 | Y20: =SUM(W20,X20) -> 0 | Z20: =_xlfn.RANK.EQ(Y20,$Y$5:$Y$104,) -> 1 | AA20: ='[7]Term 1'!$N$20 -> 0 | AB20: ='[7]Term 1'!$P$20 -> 0 | AC20: =SUM(AA20,AB20) -> 0 | AD20: =_xlfn.RANK.EQ(AC20,$AC$5:$AC$104,) -> 1 | AE20: ='[8]Term 1'!$N$20 -> 0 | AF20: ='[8]Term 1'!$P$20 -> 0 | AG20: =SUM(AE20,AF20) -> 0 | AH20: =_xlfn.RANK.EQ(AG20,$AG$5:$AG$104,) -> 1 | AI20: ='[9]Term 1'!$N$20 -> 0 | AJ20: ='[9]Term 1'!$P$20 -> 0 | AK20: =SUM(AI20,AJ20) -> 0 | AL20: =_xlfn.RANK.EQ(AK20,$AK$5:$AK$104,) -> 1 | AM20: ='[10]Term 1'!$N$20 -> 0 | AN20: ='[10]Term 1'!$P$20 -> 0 | AO20: =SUM(AM20,AN20) -> 0 | AP20: =_xlfn.RANK.EQ(AO20,$AO$5:$AO$104,) -> 1 | AQ20: =SUM(E20,I20,M20,Q20,U20,Y20,AC20,AG20,AK20,AO20) -> 0 | AR20: =_xlfn.RANK.EQ(AQ20,$AQ$5:$AQ$104,) -> 4 | AS20: ±
A21: P017 | C21: ='[1]Term 1'!$N$21 -> 0 | D21: ='[1]Term 1'!$P21 -> 0 | E21: =SUM(C21,D21) -> 0 | F21: =_xlfn.RANK.EQ(E21,$E$5:$E$104,) -> 4 | G21: ='[2]Term 1'!$N$21 -> 0 | H21: ='[2]Term 1'!$P$21 -> 0 | I21: =SUM(G21,H21) -> 0 | J21: =_xlfn.RANK.EQ(I21,$I$5:$I$104,) -> 1 | K21: ='[3]Term 1'!$N$21 -> 0 | L21: ='[3]Term 1'!$P$21 -> 0 | M21: =SUM(K21,L21) -> 0 | N21: =_xlfn.RANK.EQ(M21,$M$5:$M$104,) -> 1 | O21: ='[4]Term 1'!$N$21 -> 0 | P21: ='[4]Term 1'!$P$21 -> 0 | Q21: =SUM(O21,P21) -> 0 | R21: =_xlfn.RANK.EQ(Q21,$Q$5:$Q$104,) -> 1 | S21: ='[5]Term 1'!$N$21 -> 0 | T21: ='[5]Term 1'!$P$21 -> 0 | U21: =SUM(S21,T21) -> 0 | V21: =_xlfn.RANK.EQ(U21,$U$5:$U$104,) -> 1 | W21: ='[6]Term 1'!$N$21 -> 0 | X21: ='[6]Term 1'!$P$21 -> 0 | Y21: =SUM(W21,X21) -> 0 | Z21: =_xlfn.RANK.EQ(Y21,$Y$5:$Y$104,) -> 1 | AA21: ='[7]Term 1'!$N$21 -> 0 | AB21: ='[7]Term 1'!$P$21 -> 0 | AC21: =SUM(AA21,AB21) -> 0 | AD21: =_xlfn.RANK.EQ(AC21,$AC$5:$AC$104,) -> 1 | AE21: ='[8]Term 1'!$N$21 -> 0 | AF21: ='[8]Term 1'!$P$21 -> 0 | AG21: =SUM(AE21,AF21) -> 0 | AH21: =_xlfn.RANK.EQ(AG21,$AG$5:$AG$104,) -> 1 | AI21: ='[9]Term 1'!$N$21 -> 0 | AJ21: ='[9]Term 1'!$P$21 -> 0 | AK21: =SUM(AI21,AJ21) -> 0 | AL21: =_xlfn.RANK.EQ(AK21,$AK$5:$AK$104,) -> 1 | AM21: ='[10]Term 1'!$N$21 -> 0 | AN21: ='[10]Term 1'!$P$21 -> 0 | AO21: =SUM(AM21,AN21) -> 0 | AP21: =_xlfn.RANK.EQ(AO21,$AO$5:$AO$104,) -> 1 | AQ21: =SUM(E21,I21,M21,Q21,U21,Y21,AC21,AG21,AK21,AO21) -> 0 | AR21: =_xlfn.RANK.EQ(AQ21,$AQ$5:$AQ$104,) -> 4 | AS21: ±
A22: P018 | C22: ='[1]Term 1'!$N$22 -> 0 | D22: ='[1]Term 1'!$P22 -> 0 | E22: =SUM(C22,D22) -> 0 | F22: =_xlfn.RANK.EQ(E22,$E$5:$E$104,) -> 4 | G22: ='[2]Term 1'!$N$22 -> 0 | H22: ='[2]Term 1'!$P$22 -> 0 | I22: =SUM(G22,H22) -> 0 | J22: =_xlfn.RANK.EQ(I22,$I$5:$I$104,) -> 1 | K22: ='[3]Term 1'!$N$22 -> 0 | L22: ='[3]Term 1'!$P$22 -> 0 | M22: =SUM(K22,L22) -> 0 | N22: =_xlfn.RANK.EQ(M22,$M$5:$M$104,) -> 1 | O22: ='[4]Term 1'!$N$22 -> 0 | P22: ='[4]Term 1'!$P$22 -> 0 | Q22: =SUM(O22,P22) -> 0 | R22: =_xlfn.RANK.EQ(Q22,$Q$5:$Q$104,) -> 1 | S22: ='[5]Term 1'!$N$22 -> 0 | T22: ='[5]Term 1'!$P$22 -> 0 | U22: =SUM(S22,T22) -> 0 | V22: =_xlfn.RANK.EQ(U22,$U$5:$U$104,) -> 1 | W22: ='[6]Term 1'!$N$22 -> 0 | X22: ='[6]Term 1'!$P$22 -> 0 | Y22: =SUM(W22,X22) -> 0 | Z22: =_xlfn.RANK.EQ(Y22,$Y$5:$Y$104,) -> 1 | AA22: ='[7]Term 1'!$N$22 -> 0 | AB22: ='[7]Term 1'!$P$22 -> 0 | AC22: =SUM(AA22,AB22) -> 0 | AD22: =_xlfn.RANK.EQ(AC22,$AC$5:$AC$104,) -> 1 | AE22: ='[8]Term 1'!$N$22 -> 0 | AF22: ='[8]Term 1'!$P$22 -> 0 | AG22: =SUM(AE22,AF22) -> 0 | AH22: =_xlfn.RANK.EQ(AG22,$AG$5:$AG$104,) -> 1 | AI22: ='[9]Term 1'!$N$22 -> 0 | AJ22: ='[9]Term 1'!$P$22 -> 0 | AK22: =SUM(AI22,AJ22) -> 0 | AL22: =_xlfn.RANK.EQ(AK22,$AK$5:$AK$104,) -> 1 | AM22: ='[10]Term 1'!$N$22 -> 0 | AN22: ='[10]Term 1'!$P$22 -> 0 | AO22: =SUM(AM22,AN22) -> 0 | AP22: =_xlfn.RANK.EQ(AO22,$AO$5:$AO$104,) -> 1 | AQ22: =SUM(E22,I22,M22,Q22,U22,Y22,AC22,AG22,AK22,AO22) -> 0 | AR22: =_xlfn.RANK.EQ(AQ22,$AQ$5:$AQ$104,) -> 4 | AS22: ±
A23: P019 | C23: ='[1]Term 1'!$N$23 -> 0 | D23: ='[1]Term 1'!$P23 -> 0 | E23: =SUM(C23,D23) -> 0 | F23: =_xlfn.RANK.EQ(E23,$E$5:$E$104,) -> 4 | G23: ='[2]Term 1'!$N$23 -> 0 | H23: ='[2]Term 1'!$P$23 -> 0 | I23: =SUM(G23,H23) -> 0 | J23: =_xlfn.RANK.EQ(I23,$I$5:$I$104,) -> 1 | K23: ='[3]Term 1'!$N$23 -> 0 | L23: ='[3]Term 1'!$P$23 -> 0 | M23: =SUM(K23,L23) -> 0 | N23: =_xlfn.RANK.EQ(M23,$M$5:$M$104,) -> 1 | O23: ='[4]Term 1'!$N$23 -> 0 | P23: ='[4]Term 1'!$P$23 -> 0 | Q23: =SUM(O23,P23) -> 0 | R23: =_xlfn.RANK.EQ(Q23,$Q$5:$Q$104,) -> 1 | S23: ='[5]Term 1'!$N$23 -> 0 | T23: ='[5]Term 1'!$P$23 -> 0 | U23: =SUM(S23,T23) -> 0 | V23: =_xlfn.RANK.EQ(U23,$U$5:$U$104,) -> 1 | W23: ='[6]Term 1'!$N$23 -> 0 | X23: ='[6]Term 1'!$P$23 -> 0 | Y23: =SUM(W23,X23) -> 0 | Z23: =_xlfn.RANK.EQ(Y23,$Y$5:$Y$104,) -> 1 | AA23: ='[7]Term 1'!$N$23 -> 0 | AB23: ='[7]Term 1'!$P$23 -> 0 | AC23: =SUM(AA23,AB23) -> 0 | AD23: =_xlfn.RANK.EQ(AC23,$AC$5:$AC$104,) -> 1 | AE23: ='[8]Term 1'!$N$23 -> 0 | AF23: ='[8]Term 1'!$P$23 -> 0 | AG23: =SUM(AE23,AF23) -> 0 | AH23: =_xlfn.RANK.EQ(AG23,$AG$5:$AG$104,) -> 1 | AI23: ='[9]Term 1'!$N$23 -> 0 | AJ23: ='[9]Term 1'!$P$23 -> 0 | AK23: =SUM(AI23,AJ23) -> 0 | AL23: =_xlfn.RANK.EQ(AK23,$AK$5:$AK$104,) -> 1 | AM23: ='[10]Term 1'!$N$23 -> 0 | AN23: ='[10]Term 1'!$P$23 -> 0 | AO23: =SUM(AM23,AN23) -> 0 | AP23: =_xlfn.RANK.EQ(AO23,$AO$5:$AO$104,) -> 1 | AQ23: =SUM(E23,I23,M23,Q23,U23,Y23,AC23,AG23,AK23,AO23) -> 0 | AR23: =_xlfn.RANK.EQ(AQ23,$AQ$5:$AQ$104,) -> 4 | AS23: ±
A24: P020 | C24: ='[1]Term 1'!$N$24 -> 0 | D24: ='[1]Term 1'!$P24 -> 0 | E24: =SUM(C24,D24) -> 0 | F24: =_xlfn.RANK.EQ(E24,$E$5:$E$104,) -> 4 | G24: ='[2]Term 1'!$N$24 -> 0 | H24: ='[2]Term 1'!$P$24 -> 0 | I24: =SUM(G24,H24) -> 0 | J24: =_xlfn.RANK.EQ(I24,$I$5:$I$104,) -> 1 | K24: ='[3]Term 1'!$N$24 -> 0 | L24: ='[3]Term 1'!$P$24 -> 0 | M24: =SUM(K24,L24) -> 0 | N24: =_xlfn.RANK.EQ(M24,$M$5:$M$104,) -> 1 | O24: ='[4]Term 1'!$N$24 -> 0 | P24: ='[4]Term 1'!$P$24 -> 0 | Q24: =SUM(O24,P24) -> 0 | R24: =_xlfn.RANK.EQ(Q24,$Q$5:$Q$104,) -> 1 | S24: ='[5]Term 1'!$N$24 -> 0 | T24: ='[5]Term 1'!$P$24 -> 0 | U24: =SUM(S24,T24) -> 0 | V24: =_xlfn.RANK.EQ(U24,$U$5:$U$104,) -> 1 | W24: ='[6]Term 1'!$N$24 -> 0 | X24: ='[6]Term 1'!$P$24 -> 0 | Y24: =SUM(W24,X24) -> 0 | Z24: =_xlfn.RANK.EQ(Y24,$Y$5:$Y$104,) -> 1 | AA24: ='[7]Term 1'!$N$24 -> 0 | AB24: ='[7]Term 1'!$P$24 -> 0 | AC24: =SUM(AA24,AB24) -> 0 | AD24: =_xlfn.RANK.EQ(AC24,$AC$5:$AC$104,) -> 1 | AE24: ='[8]Term 1'!$N$24 -> 0 | AF24: ='[8]Term 1'!$P$24 -> 0 | AG24: =SUM(AE24,AF24) -> 0 | AH24: =_xlfn.RANK.EQ(AG24,$AG$5:$AG$104,) -> 1 | AI24: ='[9]Term 1'!$N$24 -> 0 | AJ24: ='[9]Term 1'!$P$24 -> 0 | AK24: =SUM(AI24,AJ24) -> 0 | AL24: =_xlfn.RANK.EQ(AK24,$AK$5:$AK$104,) -> 1 | AM24: ='[10]Term 1'!$N$24 -> 0 | AN24: ='[10]Term 1'!$P$24 -> 0 | AO24: =SUM(AM24,AN24) -> 0 | AP24: =_xlfn.RANK.EQ(AO24,$AO$5:$AO$104,) -> 1 | AQ24: =SUM(E24,I24,M24,Q24,U24,Y24,AC24,AG24,AK24,AO24) -> 0 | AR24: =_xlfn.RANK.EQ(AQ24,$AQ$5:$AQ$104,) -> 4 | AS24: ±
A25: P021 | C25: ='[1]Term 1'!$N$25 -> 0 | D25: ='[1]Term 1'!$P25 -> 0 | E25: =SUM(C25,D25) -> 0 | F25: =_xlfn.RANK.EQ(E25,$E$5:$E$104,) -> 4 | G25: ='[2]Term 1'!$N$25 -> 0 | H25: ='[2]Term 1'!$P$25 -> 0 | I25: =SUM(G25,H25) -> 0 | J25: =_xlfn.RANK.EQ(I25,$I$5:$I$104,) -> 1 | K25: ='[3]Term 1'!$N$25 -> 0 | L25: ='[3]Term 1'!$P$25 -> 0 | M25: =SUM(K25,L25) -> 0 | N25: =_xlfn.RANK.EQ(M25,$M$5:$M$104,) -> 1 | O25: ='[4]Term 1'!$N$25 -> 0 | P25: ='[4]Term 1'!$P$25 -> 0 | Q25: =SUM(O25,P25) -> 0 | R25: =_xlfn.RANK.EQ(Q25,$Q$5:$Q$104,) -> 1 | S25: ='[5]Term 1'!$N$25 -> 0 | T25: ='[5]Term 1'!$P$25 -> 0 | U25: =SUM(S25,T25) -> 0 | V25: =_xlfn.RANK.EQ(U25,$U$5:$U$104,) -> 1 | W25: ='[6]Term 1'!$N$25 -> 0 | X25: ='[6]Term 1'!$P$25 -> 0 | Y25: =SUM(W25,X25) -> 0 | Z25: =_xlfn.RANK.EQ(Y25,$Y$5:$Y$104,) -> 1 | AA25: ='[7]Term 1'!$N$25 -> 0 | AB25: ='[7]Term 1'!$P$25 -> 0 | AC25: =SUM(AA25,AB25) -> 0 | AD25: =_xlfn.RANK.EQ(AC25,$AC$5:$AC$104,) -> 1 | AE25: ='[8]Term 1'!$N$25 -> 0 | AF25: ='[8]Term 1'!$P$25 -> 0 | AG25: =SUM(AE25,AF25) -> 0 | AH25: =_xlfn.RANK.EQ(AG25,$AG$5:$AG$104,) -> 1 | AI25: ='[9]Term 1'!$N$25 -> 0 | AJ25: ='[9]Term 1'!$P$25 -> 0 | AK25: =SUM(AI25,AJ25) -> 0 | AL25: =_xlfn.RANK.EQ(AK25,$AK$5:$AK$104,) -> 1 | AM25: ='[10]Term 1'!$N$25 -> 0 | AN25: ='[10]Term 1'!$P$25 -> 0 | AO25: =SUM(AM25,AN25) -> 0 | AP25: =_xlfn.RANK.EQ(AO25,$AO$5:$AO$104,) -> 1 | AQ25: =SUM(E25,I25,M25,Q25,U25,Y25,AC25,AG25,AK25,AO25) -> 0 | AR25: =_xlfn.RANK.EQ(AQ25,$AQ$5:$AQ$104,) -> 4 | AS25: ±
A26: P022 | C26: ='[1]Term 1'!$N$26 -> 0 | D26: ='[1]Term 1'!$P26 -> 0 | E26: =SUM(C26,D26) -> 0 | F26: =_xlfn.RANK.EQ(E26,$E$5:$E$104,) -> 4 | G26: ='[2]Term 1'!$N$26 -> 0 | H26: ='[2]Term 1'!$P$26 -> 0 | I26: =SUM(G26,H26) -> 0 | J26: =_xlfn.RANK.EQ(I26,$I$5:$I$104,) -> 1 | K26: ='[3]Term 1'!$N$26 -> 0 | L26: ='[3]Term 1'!$P$26 -> 0 | M26: =SUM(K26,L26) -> 0 | N26: =_xlfn.RANK.EQ(M26,$M$5:$M$104,) -> 1 | O26: ='[4]Term 1'!$N$26 -> 0 | P26: ='[4]Term 1'!$P$26 -> 0 | Q26: =SUM(O26,P26) -> 0 | R26: =_xlfn.RANK.EQ(Q26,$Q$5:$Q$104,) -> 1 | S26: ='[5]Term 1'!$N$26 -> 0 | T26: ='[5]Term 1'!$P$26 -> 0 | U26: =SUM(S26,T26) -> 0 | V26: =_xlfn.RANK.EQ(U26,$U$5:$U$104,) -> 1 | W26: ='[6]Term 1'!$N$26 -> 0 | X26: ='[6]Term 1'!$P$26 -> 0 | Y26: =SUM(W26,X26) -> 0 | Z26: =_xlfn.RANK.EQ(Y26,$Y$5:$Y$104,) -> 1 | AA26: ='[7]Term 1'!$N$26 -> 0 | AB26: ='[7]Term 1'!$P$26 -> 0 | AC26: =SUM(AA26,AB26) -> 0 | AD26: =_xlfn.RANK.EQ(AC26,$AC$5:$AC$104,) -> 1 | AE26: ='[8]Term 1'!$N$26 -> 0 | AF26: ='[8]Term 1'!$P$26 -> 0 | AG26: =SUM(AE26,AF26) -> 0 | AH26: =_xlfn.RANK.EQ(AG26,$AG$5:$AG$104,) -> 1 | AI26: ='[9]Term 1'!$N$26 -> 0 | AJ26: ='[9]Term 1'!$P$26 -> 0 | AK26: =SUM(AI26,AJ26) -> 0 | AL26: =_xlfn.RANK.EQ(AK26,$AK$5:$AK$104,) -> 1 | AM26: ='[10]Term 1'!$N$26 -> 0 | AN26: ='[10]Term 1'!$P$26 -> 0 | AO26: =SUM(AM26,AN26) -> 0 | AP26: =_xlfn.RANK.EQ(AO26,$AO$5:$AO$104,) -> 1 | AQ26: =SUM(E26,I26,M26,Q26,U26,Y26,AC26,AG26,AK26,AO26) -> 0 | AR26: =_xlfn.RANK.EQ(AQ26,$AQ$5:$AQ$104,) -> 4 | AS26: ±
A27: P023 | C27: ='[1]Term 1'!$N$27 -> 0 | D27: ='[1]Term 1'!$P27 -> 0 | E27: =SUM(C27,D27) -> 0 | F27: =_xlfn.RANK.EQ(E27,$E$5:$E$104,) -> 4 | G27: ='[2]Term 1'!$N$27 -> 0 | H27: ='[2]Term 1'!$P$27 -> 0 | I27: =SUM(G27,H27) -> 0 | J27: =_xlfn.RANK.EQ(I27,$I$5:$I$104,) -> 1 | K27: ='[3]Term 1'!$N$27 -> 0 | L27: ='[3]Term 1'!$P$27 -> 0 | M27: =SUM(K27,L27) -> 0 | N27: =_xlfn.RANK.EQ(M27,$M$5:$M$104,) -> 1 | O27: ='[4]Term 1'!$N$27 -> 0 | P27: ='[4]Term 1'!$P$27 -> 0 | Q27: =SUM(O27,P27) -> 0 | R27: =_xlfn.RANK.EQ(Q27,$Q$5:$Q$104,) -> 1 | S27: ='[5]Term 1'!$N$27 -> 0 | T27: ='[5]Term 1'!$P$27 -> 0 | U27: =SUM(S27,T27) -> 0 | V27: =_xlfn.RANK.EQ(U27,$U$5:$U$104,) -> 1 | W27: ='[6]Term 1'!$N$27 -> 0 | X27: ='[6]Term 1'!$P$27 -> 0 | Y27: =SUM(W27,X27) -> 0 | Z27: =_xlfn.RANK.EQ(Y27,$Y$5:$Y$104,) -> 1 | AA27: ='[7]Term 1'!$N$27 -> 0 | AB27: ='[7]Term 1'!$P$27 -> 0 | AC27: =SUM(AA27,AB27) -> 0 | AD27: =_xlfn.RANK.EQ(AC27,$AC$5:$AC$104,) -> 1 | AE27: ='[8]Term 1'!$N$27 -> 0 | AF27: ='[8]Term 1'!$P$27 -> 0 | AG27: =SUM(AE27,AF27) -> 0 | AH27: =_xlfn.RANK.EQ(AG27,$AG$5:$AG$104,) -> 1 | AI27: ='[9]Term 1'!$N$27 -> 0 | AJ27: ='[9]Term 1'!$P$27 -> 0 | AK27: =SUM(AI27,AJ27) -> 0 | AL27: =_xlfn.RANK.EQ(AK27,$AK$5:$AK$104,) -> 1 | AM27: ='[10]Term 1'!$N$27 -> 0 | AN27: ='[10]Term 1'!$P$27 -> 0 | AO27: =SUM(AM27,AN27) -> 0 | AP27: =_xlfn.RANK.EQ(AO27,$AO$5:$AO$104,) -> 1 | AQ27: =SUM(E27,I27,M27,Q27,U27,Y27,AC27,AG27,AK27,AO27) -> 0 | AR27: =_xlfn.RANK.EQ(AQ27,$AQ$5:$AQ$104,) -> 4 | AS27: ±
A28: P024 | C28: ='[1]Term 1'!$N$28 -> 0 | D28: ='[1]Term 1'!$P28 -> 0 | E28: =SUM(C28,D28) -> 0 | F28: =_xlfn.RANK.EQ(E28,$E$5:$E$104,) -> 4 | G28: ='[2]Term 1'!$N$28 -> 0 | H28: ='[2]Term 1'!$P$28 -> 0 | I28: =SUM(G28,H28) -> 0 | J28: =_xlfn.RANK.EQ(I28,$I$5:$I$104,) -> 1 | K28: ='[3]Term 1'!$N$28 -> 0 | L28: ='[3]Term 1'!$P$28 -> 0 | M28: =SUM(K28,L28) -> 0 | N28: =_xlfn.RANK.EQ(M28,$M$5:$M$104,) -> 1 | O28: ='[4]Term 1'!$N$28 -> 0 | P28: ='[4]Term 1'!$P$28 -> 0 | Q28: =SUM(O28,P28) -> 0 | R28: =_xlfn.RANK.EQ(Q28,$Q$5:$Q$104,) -> 1 | S28: ='[5]Term 1'!$N$28 -> 0 | T28: ='[5]Term 1'!$P$28 -> 0 | U28: =SUM(S28,T28) -> 0 | V28: =_xlfn.RANK.EQ(U28,$U$5:$U$104,) -> 1 | W28: ='[6]Term 1'!$N$28 -> 0 | X28: ='[6]Term 1'!$P$28 -> 0 | Y28: =SUM(W28,X28) -> 0 | Z28: =_xlfn.RANK.EQ(Y28,$Y$5:$Y$104,) -> 1 | AA28: ='[7]Term 1'!$N$28 -> 0 | AB28: ='[7]Term 1'!$P$28 -> 0 | AC28: =SUM(AA28,AB28) -> 0 | AD28: =_xlfn.RANK.EQ(AC28,$AC$5:$AC$104,) -> 1 | AE28: ='[8]Term 1'!$N$28 -> 0 | AF28: ='[8]Term 1'!$P$28 -> 0 | AG28: =SUM(AE28,AF28) -> 0 | AH28: =_xlfn.RANK.EQ(AG28,$AG$5:$AG$104,) -> 1 | AI28: ='[9]Term 1'!$N$28 -> 0 | AJ28: ='[9]Term 1'!$P$28 -> 0 | AK28: =SUM(AI28,AJ28) -> 0 | AL28: =_xlfn.RANK.EQ(AK28,$AK$5:$AK$104,) -> 1 | AM28: ='[10]Term 1'!$N$28 -> 0 | AN28: ='[10]Term 1'!$P$28 -> 0 | AO28: =SUM(AM28,AN28) -> 0 | AP28: =_xlfn.RANK.EQ(AO28,$AO$5:$AO$104,) -> 1 | AQ28: =SUM(E28,I28,M28,Q28,U28,Y28,AC28,AG28,AK28,AO28) -> 0 | AR28: =_xlfn.RANK.EQ(AQ28,$AQ$5:$AQ$104,) -> 4 | AS28: ±
A29: P025 | C29: ='[1]Term 1'!$N$29 -> 0 | D29: ='[1]Term 1'!$P29 -> 0 | E29: =SUM(C29,D29) -> 0 | F29: =_xlfn.RANK.EQ(E29,$E$5:$E$104,) -> 4 | G29: ='[2]Term 1'!$N$29 -> 0 | H29: ='[2]Term 1'!$P$29 -> 0 | I29: =SUM(G29,H29) -> 0 | J29: =_xlfn.RANK.EQ(I29,$I$5:$I$104,) -> 1 | K29: ='[3]Term 1'!$N$29 -> 0 | L29: ='[3]Term 1'!$P$29 -> 0 | M29: =SUM(K29,L29) -> 0 | N29: =_xlfn.RANK.EQ(M29,$M$5:$M$104,) -> 1 | O29: ='[4]Term 1'!$N$29 -> 0 | P29: ='[4]Term 1'!$P$29 -> 0 | Q29: =SUM(O29,P29) -> 0 | R29: =_xlfn.RANK.EQ(Q29,$Q$5:$Q$104,) -> 1 | S29: ='[5]Term 1'!$N$29 -> 0 | T29: ='[5]Term 1'!$P$29 -> 0 | U29: =SUM(S29,T29) -> 0 | V29: =_xlfn.RANK.EQ(U29,$U$5:$U$104,) -> 1 | W29: ='[6]Term 1'!$N$29 -> 0 | X29: ='[6]Term 1'!$P$29 -> 0 | Y29: =SUM(W29,X29) -> 0 | Z29: =_xlfn.RANK.EQ(Y29,$Y$5:$Y$104,) -> 1 | AA29: ='[7]Term 1'!$N$29 -> 0 | AB29: ='[7]Term 1'!$P$29 -> 0 | AC29: =SUM(AA29,AB29) -> 0 | AD29: =_xlfn.RANK.EQ(AC29,$AC$5:$AC$104,) -> 1 | AE29: ='[8]Term 1'!$N$29 -> 0 | AF29: ='[8]Term 1'!$P$29 -> 0 | AG29: =SUM(AE29,AF29) -> 0 | AH29: =_xlfn.RANK.EQ(AG29,$AG$5:$AG$104,) -> 1 | AI29: ='[9]Term 1'!$N$29 -> 0 | AJ29: ='[9]Term 1'!$P$29 -> 0 | AK29: =SUM(AI29,AJ29) -> 0 | AL29: =_xlfn.RANK.EQ(AK29,$AK$5:$AK$104,) -> 1 | AM29: ='[10]Term 1'!$N$29 -> 0 | AN29: ='[10]Term 1'!$P$29 -> 0 | AO29: =SUM(AM29,AN29) -> 0 | AP29: =_xlfn.RANK.EQ(AO29,$AO$5:$AO$104,) -> 1 | AQ29: =SUM(E29,I29,M29,Q29,U29,Y29,AC29,AG29,AK29,AO29) -> 0 | AR29: =_xlfn.RANK.EQ(AQ29,$AQ$5:$AQ$104,) -> 4 | AS29: ±
A30: P026 | C30: ='[1]Term 1'!$N$30 -> 0 | D30: ='[1]Term 1'!$P30 -> 0 | E30: =SUM(C30,D30) -> 0 | F30: =_xlfn.RANK.EQ(E30,$E$5:$E$104,) -> 4 | G30: ='[2]Term 1'!$N$30 -> 0 | H30: ='[2]Term 1'!$P$30 -> 0 | I30: =SUM(G30,H30) -> 0 | J30: =_xlfn.RANK.EQ(I30,$I$5:$I$104,) -> 1 | K30: ='[3]Term 1'!$N$30 -> 0 | L30: ='[3]Term 1'!$P$30 -> 0 | M30: =SUM(K30,L30) -> 0 | N30: =_xlfn.RANK.EQ(M30,$M$5:$M$104,) -> 1 | O30: ='[4]Term 1'!$N$30 -> 0 | P30: ='[4]Term 1'!$P$30 -> 0 | Q30: =SUM(O30,P30) -> 0 | R30: =_xlfn.RANK.EQ(Q30,$Q$5:$Q$104,) -> 1 | S30: ='[5]Term 1'!$N$30 -> 0 | T30: ='[5]Term 1'!$P$30 -> 0 | U30: =SUM(S30,T30) -> 0 | V30: =_xlfn.RANK.EQ(U30,$U$5:$U$104,) -> 1 | W30: ='[6]Term 1'!$N$30 -> 0 | X30: ='[6]Term 1'!$P$30 -> 0 | Y30: =SUM(W30,X30) -> 0 | Z30: =_xlfn.RANK.EQ(Y30,$Y$5:$Y$104,) -> 1 | AA30: ='[7]Term 1'!$N$30 -> 0 | AB30: ='[7]Term 1'!$P$30 -> 0 | AC30: =SUM(AA30,AB30) -> 0 | AD30: =_xlfn.RANK.EQ(AC30,$AC$5:$AC$104,) -> 1 | AE30: ='[8]Term 1'!$N$30 -> 0 | AF30: ='[8]Term 1'!$P$30 -> 0 | AG30: =SUM(AE30,AF30) -> 0 | AH30: =_xlfn.RANK.EQ(AG30,$AG$5:$AG$104,) -> 1 | AI30: ='[9]Term 1'!$N$30 -> 0 | AJ30: ='[9]Term 1'!$P$30 -> 0 | AK30: =SUM(AI30,AJ30) -> 0 | AL30: =_xlfn.RANK.EQ(AK30,$AK$5:$AK$104,) -> 1 | AM30: ='[10]Term 1'!$N$30 -> 0 | AN30: ='[10]Term 1'!$P$30 -> 0 | AO30: =SUM(AM30,AN30) -> 0 | AP30: =_xlfn.RANK.EQ(AO30,$AO$5:$AO$104,) -> 1 | AQ30: =SUM(E30,I30,M30,Q30,U30,Y30,AC30,AG30,AK30,AO30) -> 0 | AR30: =_xlfn.RANK.EQ(AQ30,$AQ$5:$AQ$104,) -> 4 | AS30: ±
A31: P027 | C31: ='[1]Term 1'!$N$31 -> 0 | D31: ='[1]Term 1'!$P31 -> 0 | E31: =SUM(C31,D31) -> 0 | F31: =_xlfn.RANK.EQ(E31,$E$5:$E$104,) -> 4 | G31: ='[2]Term 1'!$N$31 -> 0 | H31: ='[2]Term 1'!$P$31 -> 0 | I31: =SUM(G31,H31) -> 0 | J31: =_xlfn.RANK.EQ(I31,$I$5:$I$104,) -> 1 | K31: ='[3]Term 1'!$N$31 -> 0 | L31: ='[3]Term 1'!$P$31 -> 0 | M31: =SUM(K31,L31) -> 0 | N31: =_xlfn.RANK.EQ(M31,$M$5:$M$104,) -> 1 | O31: ='[4]Term 1'!$N$31 -> 0 | P31: ='[4]Term 1'!$P$31 -> 0 | Q31: =SUM(O31,P31) -> 0 | R31: =_xlfn.RANK.EQ(Q31,$Q$5:$Q$104,) -> 1 | S31: ='[5]Term 1'!$N$31 -> 0 | T31: ='[5]Term 1'!$P$31 -> 0 | U31: =SUM(S31,T31) -> 0 | V31: =_xlfn.RANK.EQ(U31,$U$5:$U$104,) -> 1 | W31: ='[6]Term 1'!$N$31 -> 0 | X31: ='[6]Term 1'!$P$31 -> 0 | Y31: =SUM(W31,X31) -> 0 | Z31: =_xlfn.RANK.EQ(Y31,$Y$5:$Y$104,) -> 1 | AA31: ='[7]Term 1'!$N$31 -> 0 | AB31: ='[7]Term 1'!$P$31 -> 0 | AC31: =SUM(AA31,AB31) -> 0 | AD31: =_xlfn.RANK.EQ(AC31,$AC$5:$AC$104,) -> 1 | AE31: ='[8]Term 1'!$N$31 -> 0 | AF31: ='[8]Term 1'!$P$31 -> 0 | AG31: =SUM(AE31,AF31) -> 0 | AH31: =_xlfn.RANK.EQ(AG31,$AG$5:$AG$104,) -> 1 | AI31: ='[9]Term 1'!$N$31 -> 0 | AJ31: ='[9]Term 1'!$P$31 -> 0 | AK31: =SUM(AI31,AJ31) -> 0 | AL31: =_xlfn.RANK.EQ(AK31,$AK$5:$AK$104,) -> 1 | AM31: ='[10]Term 1'!$N$31 -> 0 | AN31: ='[10]Term 1'!$P$31 -> 0 | AO31: =SUM(AM31,AN31) -> 0 | AP31: =_xlfn.RANK.EQ(AO31,$AO$5:$AO$104,) -> 1 | AQ31: =SUM(E31,I31,M31,Q31,U31,Y31,AC31,AG31,AK31,AO31) -> 0 | AR31: =_xlfn.RANK.EQ(AQ31,$AQ$5:$AQ$104,) -> 4 | AS31: ±
A32: P028 | C32: ='[1]Term 1'!$N$32 -> 0 | D32: ='[1]Term 1'!$P32 -> 0 | E32: =SUM(C32,D32) -> 0 | F32: =_xlfn.RANK.EQ(E32,$E$5:$E$104,) -> 4 | G32: ='[2]Term 1'!$N$32 -> 0 | H32: ='[2]Term 1'!$P$32 -> 0 | I32: =SUM(G32,H32) -> 0 | J32: =_xlfn.RANK.EQ(I32,$I$5:$I$104,) -> 1 | K32: ='[3]Term 1'!$N$32 -> 0 | L32: ='[3]Term 1'!$P$32 -> 0 | M32: =SUM(K32,L32) -> 0 | N32: =_xlfn.RANK.EQ(M32,$M$5:$M$104,) -> 1 | O32: ='[4]Term 1'!$N$32 -> 0 | P32: ='[4]Term 1'!$P$32 -> 0 | Q32: =SUM(O32,P32) -> 0 | R32: =_xlfn.RANK.EQ(Q32,$Q$5:$Q$104,) -> 1 | S32: ='[5]Term 1'!$N$32 -> 0 | T32: ='[5]Term 1'!$P$32 -> 0 | U32: =SUM(S32,T32) -> 0 | V32: =_xlfn.RANK.EQ(U32,$U$5:$U$104,) -> 1 | W32: ='[6]Term 1'!$N$32 -> 0 | X32: ='[6]Term 1'!$P$32 -> 0 | Y32: =SUM(W32,X32) -> 0 | Z32: =_xlfn.RANK.EQ(Y32,$Y$5:$Y$104,) -> 1 | AA32: ='[7]Term 1'!$N$32 -> 0 | AB32: ='[7]Term 1'!$P$32 -> 0 | AC32: =SUM(AA32,AB32) -> 0 | AD32: =_xlfn.RANK.EQ(AC32,$AC$5:$AC$104,) -> 1 | AE32: ='[8]Term 1'!$N$32 -> 0 | AF32: ='[8]Term 1'!$P$32 -> 0 | AG32: =SUM(AE32,AF32) -> 0 | AH32: =_xlfn.RANK.EQ(AG32,$AG$5:$AG$104,) -> 1 | AI32: ='[9]Term 1'!$N$32 -> 0 | AJ32: ='[9]Term 1'!$P$32 -> 0 | AK32: =SUM(AI32,AJ32) -> 0 | AL32: =_xlfn.RANK.EQ(AK32,$AK$5:$AK$104,) -> 1 | AM32: ='[10]Term 1'!$N$32 -> 0 | AN32: ='[10]Term 1'!$P$32 -> 0 | AO32: =SUM(AM32,AN32) -> 0 | AP32: =_xlfn.RANK.EQ(AO32,$AO$5:$AO$104,) -> 1 | AQ32: =SUM(E32,I32,M32,Q32,U32,Y32,AC32,AG32,AK32,AO32) -> 0 | AR32: =_xlfn.RANK.EQ(AQ32,$AQ$5:$AQ$104,) -> 4 | AS32: ±
A33: P029 | C33: ='[1]Term 1'!$N$33 -> 0 | D33: ='[1]Term 1'!$P33 -> 0 | E33: =SUM(C33,D33) -> 0 | F33: =_xlfn.RANK.EQ(E33,$E$5:$E$104,) -> 4 | G33: ='[2]Term 1'!$N$33 -> 0 | H33: ='[2]Term 1'!$P$33 -> 0 | I33: =SUM(G33,H33) -> 0 | J33: =_xlfn.RANK.EQ(I33,$I$5:$I$104,) -> 1 | K33: ='[3]Term 1'!$N$33 -> 0 | L33: ='[3]Term 1'!$P$33 -> 0 | M33: =SUM(K33,L33) -> 0 | N33: =_xlfn.RANK.EQ(M33,$M$5:$M$104,) -> 1 | O33: ='[4]Term 1'!$N$33 -> 0 | P33: ='[4]Term 1'!$P$33 -> 0 | Q33: =SUM(O33,P33) -> 0 | R33: =_xlfn.RANK.EQ(Q33,$Q$5:$Q$104,) -> 1 | S33: ='[5]Term 1'!$N$33 -> 0 | T33: ='[5]Term 1'!$P$33 -> 0 | U33: =SUM(S33,T33) -> 0 | V33: =_xlfn.RANK.EQ(U33,$U$5:$U$104,) -> 1 | W33: ='[6]Term 1'!$N$33 -> 0 | X33: ='[6]Term 1'!$P$33 -> 0 | Y33: =SUM(W33,X33) -> 0 | Z33: =_xlfn.RANK.EQ(Y33,$Y$5:$Y$104,) -> 1 | AA33: ='[7]Term 1'!$N$33 -> 0 | AB33: ='[7]Term 1'!$P$33 -> 0 | AC33: =SUM(AA33,AB33) -> 0 | AD33: =_xlfn.RANK.EQ(AC33,$AC$5:$AC$104,) -> 1 | AE33: ='[8]Term 1'!$N$33 -> 0 | AF33: ='[8]Term 1'!$P$33 -> 0 | AG33: =SUM(AE33,AF33) -> 0 | AH33: =_xlfn.RANK.EQ(AG33,$AG$5:$AG$104,) -> 1 | AI33: ='[9]Term 1'!$N$33 -> 0 | AJ33: ='[9]Term 1'!$P$33 -> 0 | AK33: =SUM(AI33,AJ33) -> 0 | AL33: =_xlfn.RANK.EQ(AK33,$AK$5:$AK$104,) -> 1 | AM33: ='[10]Term 1'!$N$33 -> 0 | AN33: ='[10]Term 1'!$P$33 -> 0 | AO33: =SUM(AM33,AN33) -> 0 | AP33: =_xlfn.RANK.EQ(AO33,$AO$5:$AO$104,) -> 1 | AQ33: =SUM(E33,I33,M33,Q33,U33,Y33,AC33,AG33,AK33,AO33) -> 0 | AR33: =_xlfn.RANK.EQ(AQ33,$AQ$5:$AQ$104,) -> 4 | AS33: ±
A34: P030 | C34: ='[1]Term 1'!$N$34 -> 0 | D34: ='[1]Term 1'!$P34 -> 0 | E34: =SUM(C34,D34) -> 0 | F34: =_xlfn.RANK.EQ(E34,$E$5:$E$104,) -> 4 | G34: ='[2]Term 1'!$N$34 -> 0 | H34: ='[2]Term 1'!$P$34 -> 0 | I34: =SUM(G34,H34) -> 0 | J34: =_xlfn.RANK.EQ(I34,$I$5:$I$104,) -> 1 | K34: ='[3]Term 1'!$N$34 -> 0 | L34: ='[3]Term 1'!$P$34 -> 0 | M34: =SUM(K34,L34) -> 0 | N34: =_xlfn.RANK.EQ(M34,$M$5:$M$104,) -> 1 | O34: ='[4]Term 1'!$N$34 -> 0 | P34: ='[4]Term 1'!$P$34 -> 0 | Q34: =SUM(O34,P34) -> 0 | R34: =_xlfn.RANK.EQ(Q34,$Q$5:$Q$104,) -> 1 | S34: ='[5]Term 1'!$N$34 -> 0 | T34: ='[5]Term 1'!$P$34 -> 0 | U34: =SUM(S34,T34) -> 0 | V34: =_xlfn.RANK.EQ(U34,$U$5:$U$104,) -> 1 | W34: ='[6]Term 1'!$N$34 -> 0 | X34: ='[6]Term 1'!$P$34 -> 0 | Y34: =SUM(W34,X34) -> 0 | Z34: =_xlfn.RANK.EQ(Y34,$Y$5:$Y$104,) -> 1 | AA34: ='[7]Term 1'!$N$34 -> 0 | AB34: ='[7]Term 1'!$P$34 -> 0 | AC34: =SUM(AA34,AB34) -> 0 | AD34: =_xlfn.RANK.EQ(AC34,$AC$5:$AC$104,) -> 1 | AE34: ='[8]Term 1'!$N$34 -> 0 | AF34: ='[8]Term 1'!$P$34 -> 0 | AG34: =SUM(AE34,AF34) -> 0 | AH34: =_xlfn.RANK.EQ(AG34,$AG$5:$AG$104,) -> 1 | AI34: ='[9]Term 1'!$N$34 -> 0 | AJ34: ='[9]Term 1'!$P$34 -> 0 | AK34: =SUM(AI34,AJ34) -> 0 | AL34: =_xlfn.RANK.EQ(AK34,$AK$5:$AK$104,) -> 1 | AM34: ='[10]Term 1'!$N$34 -> 0 | AN34: ='[10]Term 1'!$P$34 -> 0 | AO34: =SUM(AM34,AN34) -> 0 | AP34: =_xlfn.RANK.EQ(AO34,$AO$5:$AO$104,) -> 1 | AQ34: =SUM(E34,I34,M34,Q34,U34,Y34,AC34,AG34,AK34,AO34) -> 0 | AR34: =_xlfn.RANK.EQ(AQ34,$AQ$5:$AQ$104,) -> 4 | AS34: ±
A35: P031 | C35: ='[1]Term 1'!$N$35 -> 0 | D35: ='[1]Term 1'!$P35 -> 0 | E35: =SUM(C35,D35) -> 0 | F35: =_xlfn.RANK.EQ(E35,$E$5:$E$104,) -> 4 | G35: ='[2]Term 1'!$N$35 -> 0 | H35: ='[2]Term 1'!$P$35 -> 0 | I35: =SUM(G35,H35) -> 0 | J35: =_xlfn.RANK.EQ(I35,$I$5:$I$104,) -> 1 | K35: ='[3]Term 1'!$N$35 -> 0 | L35: ='[3]Term 1'!$P$35 -> 0 | M35: =SUM(K35,L35) -> 0 | N35: =_xlfn.RANK.EQ(M35,$M$5:$M$104,) -> 1 | O35: ='[4]Term 1'!$N$35 -> 0 | P35: ='[4]Term 1'!$P$35 -> 0 | Q35: =SUM(O35,P35) -> 0 | R35: =_xlfn.RANK.EQ(Q35,$Q$5:$Q$104,) -> 1 | S35: ='[5]Term 1'!$N$35 -> 0 | T35: ='[5]Term 1'!$P$35 -> 0 | U35: =SUM(S35,T35) -> 0 | V35: =_xlfn.RANK.EQ(U35,$U$5:$U$104,) -> 1 | W35: ='[6]Term 1'!$N$35 -> 0 | X35: ='[6]Term 1'!$P$35 -> 0 | Y35: =SUM(W35,X35) -> 0 | Z35: =_xlfn.RANK.EQ(Y35,$Y$5:$Y$104,) -> 1 | AA35: ='[7]Term 1'!$N$35 -> 0 | AB35: ='[7]Term 1'!$P$35 -> 0 | AC35: =SUM(AA35,AB35) -> 0 | AD35: =_xlfn.RANK.EQ(AC35,$AC$5:$AC$104,) -> 1 | AE35: ='[8]Term 1'!$N$35 -> 0 | AF35: ='[8]Term 1'!$P$35 -> 0 | AG35: =SUM(AE35,AF35) -> 0 | AH35: =_xlfn.RANK.EQ(AG35,$AG$5:$AG$104,) -> 1 | AI35: ='[9]Term 1'!$N$35 -> 0 | AJ35: ='[9]Term 1'!$P$35 -> 0 | AK35: =SUM(AI35,AJ35) -> 0 | AL35: =_xlfn.RANK.EQ(AK35,$AK$5:$AK$104,) -> 1 | AM35: ='[10]Term 1'!$N$35 -> 0 | AN35: ='[10]Term 1'!$P$35 -> 0 | AO35: =SUM(AM35,AN35) -> 0 | AP35: =_xlfn.RANK.EQ(AO35,$AO$5:$AO$104,) -> 1 | AQ35: =SUM(E35,I35,M35,Q35,U35,Y35,AC35,AG35,AK35,AO35) -> 0 | AR35: =_xlfn.RANK.EQ(AQ35,$AQ$5:$AQ$104,) -> 4 | AS35: ±
A36: P032 | C36: ='[1]Term 1'!$N$36 -> 0 | D36: ='[1]Term 1'!$P36 -> 0 | E36: =SUM(C36,D36) -> 0 | F36: =_xlfn.RANK.EQ(E36,$E$5:$E$104,) -> 4 | G36: ='[2]Term 1'!$N$36 -> 0 | H36: ='[2]Term 1'!$P$36 -> 0 | I36: =SUM(G36,H36) -> 0 | J36: =_xlfn.RANK.EQ(I36,$I$5:$I$104,) -> 1 | K36: ='[3]Term 1'!$N$36 -> 0 | L36: ='[3]Term 1'!$P$36 -> 0 | M36: =SUM(K36,L36) -> 0 | N36: =_xlfn.RANK.EQ(M36,$M$5:$M$104,) -> 1 | O36: ='[4]Term 1'!$N$36 -> 0 | P36: ='[4]Term 1'!$P$36 -> 0 | Q36: =SUM(O36,P36) -> 0 | R36: =_xlfn.RANK.EQ(Q36,$Q$5:$Q$104,) -> 1 | S36: ='[5]Term 1'!$N$36 -> 0 | T36: ='[5]Term 1'!$P$36 -> 0 | U36: =SUM(S36,T36) -> 0 | V36: =_xlfn.RANK.EQ(U36,$U$5:$U$104,) -> 1 | W36: ='[6]Term 1'!$N$36 -> 0 | X36: ='[6]Term 1'!$P$36 -> 0 | Y36: =SUM(W36,X36) -> 0 | Z36: =_xlfn.RANK.EQ(Y36,$Y$5:$Y$104,) -> 1 | AA36: ='[7]Term 1'!$N$36 -> 0 | AB36: ='[7]Term 1'!$P$36 -> 0 | AC36: =SUM(AA36,AB36) -> 0 | AD36: =_xlfn.RANK.EQ(AC36,$AC$5:$AC$104,) -> 1 | AE36: ='[8]Term 1'!$N$36 -> 0 | AF36: ='[8]Term 1'!$P$36 -> 0 | AG36: =SUM(AE36,AF36) -> 0 | AH36: =_xlfn.RANK.EQ(AG36,$AG$5:$AG$104,) -> 1 | AI36: ='[9]Term 1'!$N$36 -> 0 | AJ36: ='[9]Term 1'!$P$36 -> 0 | AK36: =SUM(AI36,AJ36) -> 0 | AL36: =_xlfn.RANK.EQ(AK36,$AK$5:$AK$104,) -> 1 | AM36: ='[10]Term 1'!$N$36 -> 0 | AN36: ='[10]Term 1'!$P$36 -> 0 | AO36: =SUM(AM36,AN36) -> 0 | AP36: =_xlfn.RANK.EQ(AO36,$AO$5:$AO$104,) -> 1 | AQ36: =SUM(E36,I36,M36,Q36,U36,Y36,AC36,AG36,AK36,AO36) -> 0 | AR36: =_xlfn.RANK.EQ(AQ36,$AQ$5:$AQ$104,) -> 4 | AS36: ±
A37: P033 | C37: ='[1]Term 1'!$N$37 -> 0 | D37: ='[1]Term 1'!$P37 -> 0 | E37: =SUM(C37,D37) -> 0 | F37: =_xlfn.RANK.EQ(E37,$E$5:$E$104,) -> 4 | G37: ='[2]Term 1'!$N$37 -> 0 | H37: ='[2]Term 1'!$P$37 -> 0 | I37: =SUM(G37,H37) -> 0 | J37: =_xlfn.RANK.EQ(I37,$I$5:$I$104,) -> 1 | K37: ='[3]Term 1'!$N$37 -> 0 | L37: ='[3]Term 1'!$P$37 -> 0 | M37: =SUM(K37,L37) -> 0 | N37: =_xlfn.RANK.EQ(M37,$M$5:$M$104,) -> 1 | O37: ='[4]Term 1'!$N$37 -> 0 | P37: ='[4]Term 1'!$P$37 -> 0 | Q37: =SUM(O37,P37) -> 0 | R37: =_xlfn.RANK.EQ(Q37,$Q$5:$Q$104,) -> 1 | S37: ='[5]Term 1'!$N$37 -> 0 | T37: ='[5]Term 1'!$P$37 -> 0 | U37: =SUM(S37,T37) -> 0 | V37: =_xlfn.RANK.EQ(U37,$U$5:$U$104,) -> 1 | W37: ='[6]Term 1'!$N$37 -> 0 | X37: ='[6]Term 1'!$P$37 -> 0 | Y37: =SUM(W37,X37) -> 0 | Z37: =_xlfn.RANK.EQ(Y37,$Y$5:$Y$104,) -> 1 | AA37: ='[7]Term 1'!$N$37 -> 0 | AB37: ='[7]Term 1'!$P$37 -> 0 | AC37: =SUM(AA37,AB37) -> 0 | AD37: =_xlfn.RANK.EQ(AC37,$AC$5:$AC$104,) -> 1 | AE37: ='[8]Term 1'!$N$37 -> 0 | AF37: ='[8]Term 1'!$P$37 -> 0 | AG37: =SUM(AE37,AF37) -> 0 | AH37: =_xlfn.RANK.EQ(AG37,$AG$5:$AG$104,) -> 1 | AI37: ='[9]Term 1'!$N$37 -> 0 | AJ37: ='[9]Term 1'!$P$37 -> 0 | AK37: =SUM(AI37,AJ37) -> 0 | AL37: =_xlfn.RANK.EQ(AK37,$AK$5:$AK$104,) -> 1 | AM37: ='[10]Term 1'!$N$37 -> 0 | AN37: ='[10]Term 1'!$P$37 -> 0 | AO37: =SUM(AM37,AN37) -> 0 | AP37: =_xlfn.RANK.EQ(AO37,$AO$5:$AO$104,) -> 1 | AQ37: =SUM(E37,I37,M37,Q37,U37,Y37,AC37,AG37,AK37,AO37) -> 0 | AR37: =_xlfn.RANK.EQ(AQ37,$AQ$5:$AQ$104,) -> 4 | AS37: ±
A38: P034 | C38: ='[1]Term 1'!$N$38 -> 0 | D38: ='[1]Term 1'!$P38 -> 0 | E38: =SUM(C38,D38) -> 0 | F38: =_xlfn.RANK.EQ(E38,$E$5:$E$104,) -> 4 | G38: ='[2]Term 1'!$N$38 -> 0 | H38: ='[2]Term 1'!$P$38 -> 0 | I38: =SUM(G38,H38) -> 0 | J38: =_xlfn.RANK.EQ(I38,$I$5:$I$104,) -> 1 | K38: ='[3]Term 1'!$N$38 -> 0 | L38: ='[3]Term 1'!$P$38 -> 0 | M38: =SUM(K38,L38) -> 0 | N38: =_xlfn.RANK.EQ(M38,$M$5:$M$104,) -> 1 | O38: ='[4]Term 1'!$N$38 -> 0 | P38: ='[4]Term 1'!$P$38 -> 0 | Q38: =SUM(O38,P38) -> 0 | R38: =_xlfn.RANK.EQ(Q38,$Q$5:$Q$104,) -> 1 | S38: ='[5]Term 1'!$N$38 -> 0 | T38: ='[5]Term 1'!$P$38 -> 0 | U38: =SUM(S38,T38) -> 0 | V38: =_xlfn.RANK.EQ(U38,$U$5:$U$104,) -> 1 | W38: ='[6]Term 1'!$N$38 -> 0 | X38: ='[6]Term 1'!$P$38 -> 0 | Y38: =SUM(W38,X38) -> 0 | Z38: =_xlfn.RANK.EQ(Y38,$Y$5:$Y$104,) -> 1 | AA38: ='[7]Term 1'!$N$38 -> 0 | AB38: ='[7]Term 1'!$P$38 -> 0 | AC38: =SUM(AA38,AB38) -> 0 | AD38: =_xlfn.RANK.EQ(AC38,$AC$5:$AC$104,) -> 1 | AE38: ='[8]Term 1'!$N$38 -> 0 | AF38: ='[8]Term 1'!$P$38 -> 0 | AG38: =SUM(AE38,AF38) -> 0 | AH38: =_xlfn.RANK.EQ(AG38,$AG$5:$AG$104,) -> 1 | AI38: ='[9]Term 1'!$N$38 -> 0 | AJ38: ='[9]Term 1'!$P$38 -> 0 | AK38: =SUM(AI38,AJ38) -> 0 | AL38: =_xlfn.RANK.EQ(AK38,$AK$5:$AK$104,) -> 1 | AM38: ='[10]Term 1'!$N$38 -> 0 | AN38: ='[10]Term 1'!$P$38 -> 0 | AO38: =SUM(AM38,AN38) -> 0 | AP38: =_xlfn.RANK.EQ(AO38,$AO$5:$AO$104,) -> 1 | AQ38: =SUM(E38,I38,M38,Q38,U38,Y38,AC38,AG38,AK38,AO38) -> 0 | AR38: =_xlfn.RANK.EQ(AQ38,$AQ$5:$AQ$104,) -> 4 | AS38: ±
A39: P035 | C39: ='[1]Term 1'!$N$39 -> 0 | D39: ='[1]Term 1'!$P39 -> 0 | E39: =SUM(C39,D39) -> 0 | F39: =_xlfn.RANK.EQ(E39,$E$5:$E$104,) -> 4 | G39: ='[2]Term 1'!$N$39 -> 0 | H39: ='[2]Term 1'!$P$39 -> 0 | I39: =SUM(G39,H39) -> 0 | J39: =_xlfn.RANK.EQ(I39,$I$5:$I$104,) -> 1 | K39: ='[3]Term 1'!$N$39 -> 0 | L39: ='[3]Term 1'!$P$39 -> 0 | M39: =SUM(K39,L39) -> 0 | N39: =_xlfn.RANK.EQ(M39,$M$5:$M$104,) -> 1 | O39: ='[4]Term 1'!$N$39 -> 0 | P39: ='[4]Term 1'!$P$39 -> 0 | Q39: =SUM(O39,P39) -> 0 | R39: =_xlfn.RANK.EQ(Q39,$Q$5:$Q$104,) -> 1 | S39: ='[5]Term 1'!$N$39 -> 0 | T39: ='[5]Term 1'!$P$39 -> 0 | U39: =SUM(S39,T39) -> 0 | V39: =_xlfn.RANK.EQ(U39,$U$5:$U$104,) -> 1 | W39: ='[6]Term 1'!$N$39 -> 0 | X39: ='[6]Term 1'!$P$39 -> 0 | Y39: =SUM(W39,X39) -> 0 | Z39: =_xlfn.RANK.EQ(Y39,$Y$5:$Y$104,) -> 1 | AA39: ='[7]Term 1'!$N$39 -> 0 | AB39: ='[7]Term 1'!$P$39 -> 0 | AC39: =SUM(AA39,AB39) -> 0 | AD39: =_xlfn.RANK.EQ(AC39,$AC$5:$AC$104,) -> 1 | AE39: ='[8]Term 1'!$N$39 -> 0 | AF39: ='[8]Term 1'!$P$39 -> 0 | AG39: =SUM(AE39,AF39) -> 0 | AH39: =_xlfn.RANK.EQ(AG39,$AG$5:$AG$104,) -> 1 | AI39: ='[9]Term 1'!$N$39 -> 0 | AJ39: ='[9]Term 1'!$P$39 -> 0 | AK39: =SUM(AI39,AJ39) -> 0 | AL39: =_xlfn.RANK.EQ(AK39,$AK$5:$AK$104,) -> 1 | AM39: ='[10]Term 1'!$N$39 -> 0 | AN39: ='[10]Term 1'!$P$39 -> 0 | AO39: =SUM(AM39,AN39) -> 0 | AP39: =_xlfn.RANK.EQ(AO39,$AO$5:$AO$104,) -> 1 | AQ39: =SUM(E39,I39,M39,Q39,U39,Y39,AC39,AG39,AK39,AO39) -> 0 | AR39: =_xlfn.RANK.EQ(AQ39,$AQ$5:$AQ$104,) -> 4 | AS39: ±
A40: P036 | C40: ='[1]Term 1'!$N$40 -> 0 | D40: ='[1]Term 1'!$P40 -> 0 | E40: =SUM(C40,D40) -> 0 | F40: =_xlfn.RANK.EQ(E40,$E$5:$E$104,) -> 4 | G40: ='[2]Term 1'!$N$40 -> 0 | H40: ='[2]Term 1'!$P$40 -> 0 | I40: =SUM(G40,H40) -> 0 | J40: =_xlfn.RANK.EQ(I40,$I$5:$I$104,) -> 1 | K40: ='[3]Term 1'!$N$40 -> 0 | L40: ='[3]Term 1'!$P$40 -> 0 | M40: =SUM(K40,L40) -> 0 | N40: =_xlfn.RANK.EQ(M40,$M$5:$M$104,) -> 1 | O40: ='[4]Term 1'!$N$40 -> 0 | P40: ='[4]Term 1'!$P$40 -> 0 | Q40: =SUM(O40,P40) -> 0 | R40: =_xlfn.RANK.EQ(Q40,$Q$5:$Q$104,) -> 1 | S40: ='[5]Term 1'!$N$40 -> 0 | T40: ='[5]Term 1'!$P$40 -> 0 | U40: =SUM(S40,T40) -> 0 | V40: =_xlfn.RANK.EQ(U40,$U$5:$U$104,) -> 1 | W40: ='[6]Term 1'!$N$40 -> 0 | X40: ='[6]Term 1'!$P$40 -> 0 | Y40: =SUM(W40,X40) -> 0 | Z40: =_xlfn.RANK.EQ(Y40,$Y$5:$Y$104,) -> 1 | AA40: ='[7]Term 1'!$N$40 -> 0 | AB40: ='[7]Term 1'!$P$40 -> 0 | AC40: =SUM(AA40,AB40) -> 0 | AD40: =_xlfn.RANK.EQ(AC40,$AC$5:$AC$104,) -> 1 | AE40: ='[8]Term 1'!$N$40 -> 0 | AF40: ='[8]Term 1'!$P$40 -> 0 | AG40: =SUM(AE40,AF40) -> 0 | AH40: =_xlfn.RANK.EQ(AG40,$AG$5:$AG$104,) -> 1 | AI40: ='[9]Term 1'!$N$40 -> 0 | AJ40: ='[9]Term 1'!$P$40 -> 0 | AK40: =SUM(AI40,AJ40) -> 0 | AL40: =_xlfn.RANK.EQ(AK40,$AK$5:$AK$104,) -> 1 | AM40: ='[10]Term 1'!$N$40 -> 0 | AN40: ='[10]Term 1'!$P$40 -> 0 | AO40: =SUM(AM40,AN40) -> 0 | AP40: =_xlfn.RANK.EQ(AO40,$AO$5:$AO$104,) -> 1 | AQ40: =SUM(E40,I40,M40,Q40,U40,Y40,AC40,AG40,AK40,AO40) -> 0 | AR40: =_xlfn.RANK.EQ(AQ40,$AQ$5:$AQ$104,) -> 4 | AS40: ±
A41: P037 | C41: ='[1]Term 1'!$N$41 -> 0 | D41: ='[1]Term 1'!$P41 -> 0 | E41: =SUM(C41,D41) -> 0 | F41: =_xlfn.RANK.EQ(E41,$E$5:$E$104,) -> 4 | G41: ='[2]Term 1'!$N$41 -> 0 | H41: ='[2]Term 1'!$P$41 -> 0 | I41: =SUM(G41,H41) -> 0 | J41: =_xlfn.RANK.EQ(I41,$I$5:$I$104,) -> 1 | K41: ='[3]Term 1'!$N$41 -> 0 | L41: ='[3]Term 1'!$P$41 -> 0 | M41: =SUM(K41,L41) -> 0 | N41: =_xlfn.RANK.EQ(M41,$M$5:$M$104,) -> 1 | O41: ='[4]Term 1'!$N$41 -> 0 | P41: ='[4]Term 1'!$P$41 -> 0 | Q41: =SUM(O41,P41) -> 0 | R41: =_xlfn.RANK.EQ(Q41,$Q$5:$Q$104,) -> 1 | S41: ='[5]Term 1'!$N$41 -> 0 | T41: ='[5]Term 1'!$P$41 -> 0 | U41: =SUM(S41,T41) -> 0 | V41: =_xlfn.RANK.EQ(U41,$U$5:$U$104,) -> 1 | W41: ='[6]Term 1'!$N$41 -> 0 | X41: ='[6]Term 1'!$P$41 -> 0 | Y41: =SUM(W41,X41) -> 0 | Z41: =_xlfn.RANK.EQ(Y41,$Y$5:$Y$104,) -> 1 | AA41: ='[7]Term 1'!$N$41 -> 0 | AB41: ='[7]Term 1'!$P$41 -> 0 | AC41: =SUM(AA41,AB41) -> 0 | AD41: =_xlfn.RANK.EQ(AC41,$AC$5:$AC$104,) -> 1 | AE41: ='[8]Term 1'!$N$41 -> 0 | AF41: ='[8]Term 1'!$P$41 -> 0 | AG41: =SUM(AE41,AF41) -> 0 | AH41: =_xlfn.RANK.EQ(AG41,$AG$5:$AG$104,) -> 1 | AI41: ='[9]Term 1'!$N$41 -> 0 | AJ41: ='[9]Term 1'!$P$41 -> 0 | AK41: =SUM(AI41,AJ41) -> 0 | AL41: =_xlfn.RANK.EQ(AK41,$AK$5:$AK$104,) -> 1 | AM41: ='[10]Term 1'!$N$41 -> 0 | AN41: ='[10]Term 1'!$P$41 -> 0 | AO41: =SUM(AM41,AN41) -> 0 | AP41: =_xlfn.RANK.EQ(AO41,$AO$5:$AO$104,) -> 1 | AQ41: =SUM(E41,I41,M41,Q41,U41,Y41,AC41,AG41,AK41,AO41) -> 0 | AR41: =_xlfn.RANK.EQ(AQ41,$AQ$5:$AQ$104,) -> 4 | AS41: ±
...

Sheet Term 2 Summary Sheet
A1: TERM 2 TEACHER'S SUMMARY SHEET
A2: ID# | B2: STUDENT NAME | C2: MATHEMATICS | G2: ENGLISH LANGUAGE | K2: SOCIAL STUDIES | O2: INTEGRATED SCIENCE | S2: CREATIVE ARTS | W2: CAREER TECHNOLOGY | AA2: COMPUTING | AE2: RELIGIOUS & MORAL EDUCATION | AI2: FRENCH | AM2: GHANAIAN LANGUAGE (TWI) | AQ2: HIGH SCORE | AR2: RANK | AS2: ATTENDANCE | AT2: CONDUCT | AU2: LEARNERS INTEREST | AV2: CLASS FACILITATOR'S REMARKS
C3: CS | D3: ES | E3: TL | F3: PN | G3: CS | H3: ES | I3: TL | J3: PN | K3: CS | L3: ES | M3: TL | N3: PN | O3: CS | P3: ES | Q3: TL | R3: PN | S3: CS | T3: ES | U3: TL | V3: PN | W3: CS | X3: ES | Y3: TL | Z3: PN | AA3: CS | AB3: ES | AC3: TL | AD3: PN | AE3: CS | AF3: ES | AG3: TL | AH3: PN | AI3: CS | AJ3: ES | AK3: TL | AL3: PN | AM3: CS | AN3: ES | AO3: TL | AP3: PN
A5: O001 | B5: Benjamin Jackson | C5: ='[1]Term 2'!$N$5 -> 36 | D5: ='[1]Term 2'!$P$5 -> 44 | E5: =SUM(C5,D5) -> 80 | F5: =_xlfn.RANK.EQ(E5,$E$5:$E$104,) -> 2 | G5: ='[2]Term 2'!$N$5 -> 0 | H5: ='[2]Term 2'!$P$5 -> 0 | I5: =SUM(G5,H5) -> 0 | J5: =_xlfn.RANK.EQ(I5,$I$5:$I$104,) -> 1 | K5: ='[3]Term 2'!$N$5 -> 0 | L5: ='[3]Term 2'!$P$5 -> 0 | M5: =SUM(K5,L5) -> 0 | N5: =_xlfn.RANK.EQ(M5,$M$5:$M$104,) -> 1 | O5: ='[4]Term 2'!$N$5 -> 0 | P5: ='[4]Term 2'!$P$5 -> 0 | Q5: =SUM(O5,P5) -> 0 | R5: =_xlfn.RANK.EQ(Q5,$Q$5:$Q$104,) -> 1 | S5: ='[5]Term 2'!$N$5 -> 0 | T5: ='[5]Term 2'!$P$5 -> 0 | U5: =SUM(S5,T5) -> 0 | V5: =_xlfn.RANK.EQ(U5,$U$5:$U$104,) -> 1 | W5: ='[6]Term 2'!$N$5 -> 0 | X5: ='[6]Term 2'!$P$5 -> 0 | Y5: =SUM(W5,X5) -> 0 | Z5: =_xlfn.RANK.EQ(Y5,$Y$5:$Y$104,) -> 1 | AA5: ='[7]Term 2'!$N$5 -> 0 | AB5: ='[7]Term 2'!$P$5 -> 0 | AC5: =SUM(AA5,AB5) -> 0 | AD5: =_xlfn.RANK.EQ(AC5,$AC$5:$AC$104,) -> 1 | AE5: ='[8]Term 2'!$N$5 -> 0 | AF5: ='[8]Term 2'!$P$5 -> 0 | AG5: =SUM(AE5,AF5) -> 0 | AH5: =_xlfn.RANK.EQ(AG5,$AG$5:$AG$104,) -> 1 | AI5: ='[9]Term 2'!$N$5 -> 0 | AJ5: ='[9]Term 2'!$P$5 -> 0 | AK5: =SUM(AI5,AJ5) -> 0 | AL5: =_xlfn.RANK.EQ(AK5,$AK$5:$AK$104,) -> 1 | AM5: ='[10]Term 2'!$N$5 -> 0 | AN5: ='[10]Term 2'!$P$5 -> 0 | AO5: =SUM(AM5,AN5) -> 0 | AP5: =_xlfn.RANK.EQ(AO5,$AO$5:$AO$104,) -> 1 | AQ5: =SUM(E5,I5,M5,Q5,U5,Y5,AC5,AG5,AK5,AO5) -> 80 | AR5: =_xlfn.RANK.EQ(AQ5,$AQ$5:$AQ$104,) -> 2 | AS5: ±
A6: O002 | B6: Henry Franklin | C6: ='[1]Term 2'!$N$6 -> 38.5 | D6: ='[1]Term 2'!$P$6 -> 45.5 | E6: =SUM(C6,D6) -> 84 | F6: =_xlfn.RANK.EQ(E6,$E$5:$E$104,) -> 1 | G6: ='[2]Term 2'!$N$6 -> 0 | H6: ='[2]Term 2'!$P$6 -> 0 | I6: =SUM(G6,H6) -> 0 | J6: =_xlfn.RANK.EQ(I6,$I$5:$I$104,) -> 1 | K6: ='[3]Term 2'!$N$6 -> 0 | L6: ='[3]Term 2'!$P$6 -> 0 | M6: =SUM(K6,L6) -> 0 | N6: =_xlfn.RANK.EQ(M6,$M$5:$M$104,) -> 1 | O6: ='[4]Term 2'!$N$6 -> 0 | P6: ='[4]Term 2'!$P$6 -> 0 | Q6: =SUM(O6,P6) -> 0 | R6: =_xlfn.RANK.EQ(Q6,$Q$5:$Q$104,) -> 1 | S6: ='[5]Term 2'!$N$6 -> 0 | T6: ='[5]Term 2'!$P$6 -> 0 | U6: =SUM(S6,T6) -> 0 | V6: =_xlfn.RANK.EQ(U6,$U$5:$U$104,) -> 1 | W6: ='[6]Term 2'!$N$6 -> 0 | X6: ='[6]Term 2'!$P$6 -> 0 | Y6: =SUM(W6,X6) -> 0 | Z6: =_xlfn.RANK.EQ(Y6,$Y$5:$Y$104,) -> 1 | AA6: ='[7]Term 2'!$N$6 -> 0 | AB6: ='[7]Term 2'!$P$6 -> 0 | AC6: =SUM(AA6,AB6) -> 0 | AD6: =_xlfn.RANK.EQ(AC6,$AC$5:$AC$104,) -> 1 | AE6: ='[8]Term 2'!$N$6 -> 0 | AF6: ='[8]Term 2'!$P$6 -> 0 | AG6: =SUM(AE6,AF6) -> 0 | AH6: =_xlfn.RANK.EQ(AG6,$AG$5:$AG$104,) -> 1 | AI6: ='[9]Term 2'!$N$6 -> 0 | AJ6: ='[9]Term 2'!$P$6 -> 0 | AK6: =SUM(AI6,AJ6) -> 0 | AL6: =_xlfn.RANK.EQ(AK6,$AK$5:$AK$104,) -> 1 | AM6: ='[10]Term 2'!$N$6 -> 0 | AN6: ='[10]Term 2'!$P$6 -> 0 | AO6: =SUM(AM6,AN6) -> 0 | AP6: =_xlfn.RANK.EQ(AO6,$AO$5:$AO$104,) -> 1 | AQ6: =SUM(E6,I6,M6,Q6,U6,Y6,AC6,AG6,AK6,AO6) -> 84 | AR6: =_xlfn.RANK.EQ(AQ6,$AQ$5:$AQ$104,) -> 1 | AS6: ±
